Workbook

Sheet 首页+选择功能
B1: 省份按月电价查询
A2: 省份 | B2: 江苏
A3: 月份 | B3: 年均
A4: 电压等级 | B4: 两部制220kV
A5: 综合平段电价 | B5: {=_xlfn.XLOOKUP($B$3,$C$6:$O$6,$C$12:$O$12)}
A6: 序号 | B6: 2026年电价表 | C6: 46023 | D6: 46054 | E6: 46082 | F6: 46113 | G6: 46143 | H6: 46174 | I6: 46204 | J6: 46235 | K6: 46266 | L6: 46296 | M6: 46327 | N6: 46357 | O6: 年均 | P6: 趋势图
A7: 1 | B7: 代理购电价格 | C7: {=_xlfn.XLOOKUP($B$2&$B7,'总表-2026'!$B$3:'总表-2026'!$B$253&'总表-2026'!$C$3:'总表-2026'!$C$253,'总表-2026'!D$3:'总表-2026'!D$253)} | D7: {=_xlfn.XLOOKUP($B$2&$B7,'总表-2026'!$B$3:'总表-2026'!$B$253&'总表-2026'!$C$3:'总表-2026'!$C$253,'总表-2026'!E$3:'总表-2026'!E$253)} | E7: {=_xlfn.XLOOKUP($B$2&$B7,'总表-2026'!$B$3:'总表-2026'!$B$253&'总表-2026'!$C$3:'总表-2026'!$C$253,'总表-2026'!F$3:'总表-2026'!F$253)} | F7: {=_xlfn.XLOOKUP($B$2&$B7,'总表-2026'!$B$3:'总表-2026'!$B$253&'总表-2026'!$C$3:'总表-2026'!$C$253,'总表-2026'!G$3:'总表-2026'!G$253)} | G7: {=_xlfn.XLOOKUP($B$2&$B7,'总表-2026'!$B$3:'总表-2026'!$B$253&'总表-2026'!$C$3:'总表-2026'!$C$253,'总表-2026'!H$3:'总表-2026'!H$253)} | H7: {=_xlfn.XLOOKUP($B$2&$B7,'总表-2026'!$B$3:'总表-2026'!$B$253&'总表-2026'!$C$3:'总表-2026'!$C$253,'总表-2026'!I$3:'总表-2026'!I$253)} | I7: {=_xlfn.XLOOKUP($B$2&$B7,'总表-2026'!$B$3:'总表-2026'!$B$253&'总表-2026'!$C$3:'总表-2026'!$C$253,'总表-2026'!J$3:'总表-2026'!J$253)} | J7: {=_xlfn.XLOOKUP($B$2&$B7,'总表-2026'!$B$3:'总表-2026'!$B$253&'总表-2026'!$C$3:'总表-2026'!$C$253,'总表-2026'!K$3:'总表-2026'!K$253)} | ... O7: {=_xlfn.XLOOKUP($B$2&$B7,'总表-2026'!$B$3:'总表-2026'!$B$253&'总表-2026'!$C$3:'总表-2026'!$C$253,'总表-2026'!P$3:'总表-2026'!P$253)}
A8: 2 | B8: 上网环节线损电价 | C8: {=_xlfn.XLOOKUP($B$2&$B8,'总表-2026'!$B$3:'总表-2026'!$B$253&'总表-2026'!$C$3:'总表-2026'!$C$253,'总表-2026'!D$3:'总表-2026'!D$253)} | D8: {=_xlfn.XLOOKUP($B$2&$B8,'总表-2026'!$B$3:'总表-2026'!$B$253&'总表-2026'!$C$3:'总表-2026'!$C$253,'总表-2026'!E$3:'总表-2026'!E$253)} | E8: {=_xlfn.XLOOKUP($B$2&$B8,'总表-2026'!$B$3:'总表-2026'!$B$253&'总表-2026'!$C$3:'总表-2026'!$C$253,'总表-2026'!F$3:'总表-2026'!F$253)} | F8: {=_xlfn.XLOOKUP($B$2&$B8,'总表-2026'!$B$3:'总表-2026'!$B$253&'总表-2026'!$C$3:'总表-2026'!$C$253,'总表-2026'!G$3:'总表-2026'!G$253)} | G8: {=_xlfn.XLOOKUP($B$2&$B8,'总表-2026'!$B$3:'总表-2026'!$B$253&'总表-2026'!$C$3:'总表-2026'!$C$253,'总表-2026'!H$3:'总表-2026'!H$253)} | H8: {=_xlfn.XLOOKUP($B$2&$B8,'总表-2026'!$B$3:'总表-2026'!$B$253&'总表-2026'!$C$3:'总表-2026'!$C$253,'总表-2026'!I$3:'总表-2026'!I$253)} | I8: {=_xlfn.XLOOKUP($B$2&$B8,'总表-2026'!$B$3:'总表-2026'!$B$253&'总表-2026'!$C$3:'总表-2026'!$C$253,'总表-2026'!J$3:'总表-2026'!J$253)} | J8: {=_xlfn.XLOOKUP($B$2&$B8,'总表-2026'!$B$3:'总表-2026'!$B$253&'总表-2026'!$C$3:'总表-2026'!$C$253,'总表-2026'!K$3:'总表-2026'!K$253)} | ... O8: {=_xlfn.XLOOKUP($B$2&$B8,'总表-2026'!$B$3:'总表-2026'!$B$253&'总表-2026'!$C$3:'总表-2026'!$C$253,'总表-2026'!P$3:'总表-2026'!P$253)}
A9: 3 | B9: 电度输配电价 | C9: {=_xlfn.XLOOKUP($B$2&$B9,'总表-2026'!$B$3:'总表-2026'!$B$253&'总表-2026'!$C$3:'总表-2026'!$C$253,'总表-2026'!D$3:'总表-2026'!D$253)} | D9: {=_xlfn.XLOOKUP($B$2&$B9,'总表-2026'!$B$3:'总表-2026'!$B$253&'总表-2026'!$C$3:'总表-2026'!$C$253,'总表-2026'!E$3:'总表-2026'!E$253)} | E9: {=_xlfn.XLOOKUP($B$2&$B9,'总表-2026'!$B$3:'总表-2026'!$B$253&'总表-2026'!$C$3:'总表-2026'!$C$253,'总表-2026'!F$3:'总表-2026'!F$253)} | F9: {=_xlfn.XLOOKUP($B$2&$B9,'总表-2026'!$B$3:'总表-2026'!$B$253&'总表-2026'!$C$3:'总表-2026'!$C$253,'总表-2026'!G$3:'总表-2026'!G$253)} | G9: {=_xlfn.XLOOKUP($B$2&$B9,'总表-2026'!$B$3:'总表-2026'!$B$253&'总表-2026'!$C$3:'总表-2026'!$C$253,'总表-2026'!H$3:'总表-2026'!H$253)} | H9: {=_xlfn.XLOOKUP($B$2&$B9,'总表-2026'!$B$3:'总表-2026'!$B$253&'总表-2026'!$C$3:'总表-2026'!$C$253,'总表-2026'!I$3:'总表-2026'!I$253)} | I9: {=_xlfn.XLOOKUP($B$2&$B9,'总表-2026'!$B$3:'总表-2026'!$B$253&'总表-2026'!$C$3:'总表-2026'!$C$253,'总表-2026'!J$3:'总表-2026'!J$253)} | J9: {=_xlfn.XLOOKUP($B$2&$B9,'总表-2026'!$B$3:'总表-2026'!$B$253&'总表-2026'!$C$3:'总表-2026'!$C$253,'总表-2026'!K$3:'总表-2026'!K$253)} | ... O9: {=_xlfn.XLOOKUP($B$2&$B9,'总表-2026'!$B$3:'总表-2026'!$B$253&'总表-2026'!$C$3:'总表-2026'!$C$253,'总表-2026'!P$3:'总表-2026'!P$253)}
A10: 4 | B10: 政府性基金及附加 | C10: {=_xlfn.XLOOKUP($B$2&$B10,'总表-2026'!$B$3:'总表-2026'!$B$253&'总表-2026'!$C$3:'总表-2026'!$C$253,'总表-2026'!D$3:'总表-2026'!D$253)} | D10: {=_xlfn.XLOOKUP($B$2&$B10,'总表-2026'!$B$3:'总表-2026'!$B$253&'总表-2026'!$C$3:'总表-2026'!$C$253,'总表-2026'!E$3:'总表-2026'!E$253)} | E10: {=_xlfn.XLOOKUP($B$2&$B10,'总表-2026'!$B$3:'总表-2026'!$B$253&'总表-2026'!$C$3:'总表-2026'!$C$253,'总表-2026'!F$3:'总表-2026'!F$253)} | F10: {=_xlfn.XLOOKUP($B$2&$B10,'总表-2026'!$B$3:'总表-2026'!$B$253&'总表-2026'!$C$3:'总表-2026'!$C$253,'总表-2026'!G$3:'总表-2026'!G$253)} | G10: {=_xlfn.XLOOKUP($B$2&$B10,'总表-2026'!$B$3:'总表-2026'!$B$253&'总表-2026'!$C$3:'总表-2026'!$C$253,'总表-2026'!H$3:'总表-2026'!H$253)} | H10: {=_xlfn.XLOOKUP($B$2&$B10,'总表-2026'!$B$3:'总表-2026'!$B$253&'总表-2026'!$C$3:'总表-2026'!$C$253,'总表-2026'!I$3:'总表-2026'!I$253)} | I10: {=_xlfn.XLOOKUP($B$2&$B10,'总表-2026'!$B$3:'总表-2026'!$B$253&'总表-2026'!$C$3:'总表-2026'!$C$253,'总表-2026'!J$3:'总表-2026'!J$253)} | J10: {=_xlfn.XLOOKUP($B$2&$B10,'总表-2026'!$B$3:'总表-2026'!$B$253&'总表-2026'!$C$3:'总表-2026'!$C$253,'总表-2026'!K$3:'总表-2026'!K$253)} | ... O10: {=_xlfn.XLOOKUP($B$2&$B10,'总表-2026'!$B$3:'总表-2026'!$B$253&'总表-2026'!$C$3:'总表-2026'!$C$253,'总表-2026'!P$3:'总表-2026'!P$253)}
A11: 5 | B11: 系统运行费折价 | C11: {=_xlfn.XLOOKUP($B$2&$B11,'总表-2026'!$B$3:'总表-2026'!$B$253&'总表-2026'!$C$3:'总表-2026'!$C$253,'总表-2026'!D$3:'总表-2026'!D$253)} | D11: {=_xlfn.XLOOKUP($B$2&$B11,'总表-2026'!$B$3:'总表-2026'!$B$253&'总表-2026'!$C$3:'总表-2026'!$C$253,'总表-2026'!E$3:'总表-2026'!E$253)} | E11: {=_xlfn.XLOOKUP($B$2&$B11,'总表-2026'!$B$3:'总表-2026'!$B$253&'总表-2026'!$C$3:'总表-2026'!$C$253,'总表-2026'!F$3:'总表-2026'!F$253)} | F11: {=_xlfn.XLOOKUP($B$2&$B11,'总表-2026'!$B$3:'总表-2026'!$B$253&'总表-2026'!$C$3:'总表-2026'!$C$253,'总表-2026'!G$3:'总表-2026'!G$253)} | G11: {=_xlfn.XLOOKUP($B$2&$B11,'总表-2026'!$B$3:'总表-2026'!$B$253&'总表-2026'!$C$3:'总表-2026'!$C$253,'总表-2026'!H$3:'总表-2026'!H$253)} | H11: {=_xlfn.XLOOKUP($B$2&$B11,'总表-2026'!$B$3:'总表-2026'!$B$253&'总表-2026'!$C$3:'总表-2026'!$C$253,'总表-2026'!I$3:'总表-2026'!I$253)} | I11: {=_xlfn.XLOOKUP($B$2&$B11,'总表-2026'!$B$3:'总表-2026'!$B$253&'总表-2026'!$C$3:'总表-2026'!$C$253,'总表-2026'!J$3:'总表-2026'!J$253)} | J11: {=_xlfn.XLOOKUP($B$2&$B11,'总表-2026'!$B$3:'总表-2026'!$B$253&'总表-2026'!$C$3:'总表-2026'!$C$253,'总表-2026'!K$3:'总表-2026'!K$253)} | ... O11: {=_xlfn.XLOOKUP($B$2&$B11,'总表-2026'!$B$3:'总表-2026'!$B$253&'总表-2026'!$C$3:'总表-2026'!$C$253,'总表-2026'!P$3:'总表-2026'!P$253)}
A12: 6 | B12: 综合平段电价--电网代购 | C12: {=_xlfn.XLOOKUP($B$2&$B12,'总表-2026'!$B$3:'总表-2026'!$B$253&'总表-2026'!$C$3:'总表-2026'!$C$253,'总表-2026'!D$3:'总表-2026'!D$253)} | D12: {=_xlfn.XLOOKUP($B$2&$B12,'总表-2026'!$B$3:'总表-2026'!$B$253&'总表-2026'!$C$3:'总表-2026'!$C$253,'总表-2026'!E$3:'总表-2026'!E$253)} | E12: {=_xlfn.XLOOKUP($B$2&$B12,'总表-2026'!$B$3:'总表-2026'!$B$253&'总表-2026'!$C$3:'总表-2026'!$C$253,'总表-2026'!F$3:'总表-2026'!F$253)} | F12: {=_xlfn.XLOOKUP($B$2&$B12,'总表-2026'!$B$3:'总表-2026'!$B$253&'总表-2026'!$C$3:'总表-2026'!$C$253,'总表-2026'!G$3:'总表-2026'!G$253)} | G12: {=_xlfn.XLOOKUP($B$2&$B12,'总表-2026'!$B$3:'总表-2026'!$B$253&'总表-2026'!$C$3:'总表-2026'!$C$253,'总表-2026'!H$3:'总表-2026'!H$253)} | H12: {=_xlfn.XLOOKUP($B$2&$B12,'总表-2026'!$B$3:'总表-2026'!$B$253&'总表-2026'!$C$3:'总表-2026'!$C$253,'总表-2026'!I$3:'总表-2026'!I$253)} | I12: {=_xlfn.XLOOKUP($B$2&$B12,'总表-2026'!$B$3:'总表-2026'!$B$253&'总表-2026'!$C$3:'总表-2026'!$C$253,'总表-2026'!J$3:'总表-2026'!J$253)} | J12: {=_xlfn.XLOOKUP($B$2&$B12,'总表-2026'!$B$3:'总表-2026'!$B$253&'总表-2026'!$C$3:'总表-2026'!$C$253,'总表-2026'!K$3:'总表-2026'!K$253)} | ... O12: {=_xlfn.XLOOKUP($B$2&$B12,'总表-2026'!$B$3:'总表-2026'!$B$253&'总表-2026'!$C$3:'总表-2026'!$C$253,'总表-2026'!P$3:'总表-2026'!P$253)}
A13: 7 | B13: 入市交易购电价格 | C13: {=_xlfn.XLOOKUP($B$2&$B13,'总表-2026'!$B$3:'总表-2026'!$B$253&'总表-2026'!$C$3:'总表-2026'!$C$253,'总表-2026'!D$3:'总表-2026'!D$253)} | D13: {=_xlfn.XLOOKUP($B$2&$B13,'总表-2026'!$B$3:'总表-2026'!$B$253&'总表-2026'!$C$3:'总表-2026'!$C$253,'总表-2026'!E$3:'总表-2026'!E$253)} | E13: {=_xlfn.XLOOKUP($B$2&$B13,'总表-2026'!$B$3:'总表-2026'!$B$253&'总表-2026'!$C$3:'总表-2026'!$C$253,'总表-2026'!F$3:'总表-2026'!F$253)} | F13: {=_xlfn.XLOOKUP($B$2&$B13,'总表-2026'!$B$3:'总表-2026'!$B$253&'总表-2026'!$C$3:'总表-2026'!$C$253,'总表-2026'!G$3:'总表-2026'!G$253)} | G13: {=_xlfn.XLOOKUP($B$2&$B13,'总表-2026'!$B$3:'总表-2026'!$B$253&'总表-2026'!$C$3:'总表-2026'!$C$253,'总表-2026'!H$3:'总表-2026'!H$253)} | H13: {=_xlfn.XLOOKUP($B$2&$B13,'总表-2026'!$B$3:'总表-2026'!$B$253&'总表-2026'!$C$3:'总表-2026'!$C$253,'总表-2026'!I$3:'总表-2026'!I$253)} | I13: {=_xlfn.XLOOKUP($B$2&$B13,'总表-2026'!$B$3:'总表-2026'!$B$253&'总表-2026'!$C$3:'总表-2026'!$C$253,'总表-2026'!J$3:'总表-2026'!J$253)} | J13: {=_xlfn.XLOOKUP($B$2&$B13,'总表-2026'!$B$3:'总表-2026'!$B$253&'总表-2026'!$C$3:'总表-2026'!$C$253,'总表-2026'!K$3:'总表-2026'!K$253)} | ... O13: {=_xlfn.XLOOKUP($B$2&$B13,'总表-2026'!$B$3:'总表-2026'!$B$253&'总表-2026'!$C$3:'总表-2026'!$C$253,'总表-2026'!P$3:'总表-2026'!P$253)}
A14: 8 | B14: 综合平段电价--入市交易 | C14: {=_xlfn.XLOOKUP($B$2&$B14,'总表-2026'!$B$3:'总表-2026'!$B$253&'总表-2026'!$C$3:'总表-2026'!$C$253,'总表-2026'!D$3:'总表-2026'!D$253)} | D14: {=_xlfn.XLOOKUP($B$2&$B14,'总表-2026'!$B$3:'总表-2026'!$B$253&'总表-2026'!$C$3:'总表-2026'!$C$253,'总表-2026'!E$3:'总表-2026'!E$253)} | E14: {=_xlfn.XLOOKUP($B$2&$B14,'总表-2026'!$B$3:'总表-2026'!$B$253&'总表-2026'!$C$3:'总表-2026'!$C$253,'总表-2026'!F$3:'总表-2026'!F$253)} | F14: {=_xlfn.XLOOKUP($B$2&$B14,'总表-2026'!$B$3:'总表-2026'!$B$253&'总表-2026'!$C$3:'总表-2026'!$C$253,'总表-2026'!G$3:'总表-2026'!G$253)} | G14: {=_xlfn.XLOOKUP($B$2&$B14,'总表-2026'!$B$3:'总表-2026'!$B$253&'总表-2026'!$C$3:'总表-2026'!$C$253,'总表-2026'!H$3:'总表-2026'!H$253)} | H14: {=_xlfn.XLOOKUP($B$2&$B14,'总表-2026'!$B$3:'总表-2026'!$B$253&'总表-2026'!$C$3:'总表-2026'!$C$253,'总表-2026'!I$3:'总表-2026'!I$253)} | I14: {=_xlfn.XLOOKUP($B$2&$B14,'总表-2026'!$B$3:'总表-2026'!$B$253&'总表-2026'!$C$3:'总表-2026'!$C$253,'总表-2026'!J$3:'总表-2026'!J$253)} | J14: {=_xlfn.XLOOKUP($B$2&$B14,'总表-2026'!$B$3:'总表-2026'!$B$253&'总表-2026'!$C$3:'总表-2026'!$C$253,'总表-2026'!K$3:'总表-2026'!K$253)} | ... O14: {=_xlfn.XLOOKUP($B$2&$B14,'总表-2026'!$B$3:'总表-2026'!$B$253&'总表-2026'!$C$3:'总表-2026'!$C$253,'总表-2026'!P$3:'总表-2026'!P$253)}
A34: 序号 | B34: 2025年电价表 | C34: 45658 | D34: 45689 | E34: 45717 | F34: 45748 | G34: 45778 | H34: 45809 | I34: 45839 | J34: 45870 | K34: 45901 | L34: 45931 | M34: 45962 | N34: 45992 | O34: 年均 | P34: 趋势图
A35: 1 | B35: 代理购电价格 | C35: {=_xlfn.XLOOKUP($B$2&$B35,'总表-2025'!$B$3:'总表-2025'!$B$253&'总表-2025'!$C$3:'总表-2025'!$C$253,'总表-2025'!D$3:'总表-2025'!D$253)} | D35: {=_xlfn.XLOOKUP($B$2&$B35,'总表-2025'!$B$3:'总表-2025'!$B$253&'总表-2025'!$C$3:'总表-2025'!$C$253,'总表-2025'!E$3:'总表-2025'!E$253)} | E35: {=_xlfn.XLOOKUP($B$2&$B35,'总表-2025'!$B$3:'总表-2025'!$B$253&'总表-2025'!$C$3:'总表-2025'!$C$253,'总表-2025'!F$3:'总表-2025'!F$253)} | F35: {=_xlfn.XLOOKUP($B$2&$B35,'总表-2025'!$B$3:'总表-2025'!$B$253&'总表-2025'!$C$3:'总表-2025'!$C$253,'总表-2025'!G$3:'总表-2025'!G$253)} | G35: {=_xlfn.XLOOKUP($B$2&$B35,'总表-2025'!$B$3:'总表-2025'!$B$253&'总表-2025'!$C$3:'总表-2025'!$C$253,'总表-2025'!H$3:'总表-2025'!H$253)} | H35: {=_xlfn.XLOOKUP($B$2&$B35,'总表-2025'!$B$3:'总表-2025'!$B$253&'总表-2025'!$C$3:'总表-2025'!$C$253,'总表-2025'!I$3:'总表-2025'!I$253)} | I35: {=_xlfn.XLOOKUP($B$2&$B35,'总表-2025'!$B$3:'总表-2025'!$B$253&'总表-2025'!$C$3:'总表-2025'!$C$253,'总表-2025'!J$3:'总表-2025'!J$253)} | J35: {=_xlfn.XLOOKUP($B$2&$B35,'总表-2025'!$B$3:'总表-2025'!$B$253&'总表-2025'!$C$3:'总表-2025'!$C$253,'总表-2025'!K$3:'总表-2025'!K$253)} | ... O35: {=_xlfn.XLOOKUP($B$2&$B35,'总表-2025'!$B$3:'总表-2025'!$B$253&'总表-2025'!$C$3:'总表-2025'!$C$253,'总表-2025'!P$3:'总表-2025'!P$253)}
A36: 2 | B36: 上网环节线损电价 | C36: {=_xlfn.XLOOKUP($B$2&$B36,'总表-2025'!$B$3:'总表-2025'!$B$253&'总表-2025'!$C$3:'总表-2025'!$C$253,'总表-2025'!D$3:'总表-2025'!D$253)} | D36: {=_xlfn.XLOOKUP($B$2&$B36,'总表-2025'!$B$3:'总表-2025'!$B$253&'总表-2025'!$C$3:'总表-2025'!$C$253,'总表-2025'!E$3:'总表-2025'!E$253)} | E36: {=_xlfn.XLOOKUP($B$2&$B36,'总表-2025'!$B$3:'总表-2025'!$B$253&'总表-2025'!$C$3:'总表-2025'!$C$253,'总表-2025'!F$3:'总表-2025'!F$253)} | F36: {=_xlfn.XLOOKUP($B$2&$B36,'总表-2025'!$B$3:'总表-2025'!$B$253&'总表-2025'!$C$3:'总表-2025'!$C$253,'总表-2025'!G$3:'总表-2025'!G$253)} | G36: {=_xlfn.XLOOKUP($B$2&$B36,'总表-2025'!$B$3:'总表-2025'!$B$253&'总表-2025'!$C$3:'总表-2025'!$C$253,'总表-2025'!H$3:'总表-2025'!H$253)} | H36: {=_xlfn.XLOOKUP($B$2&$B36,'总表-2025'!$B$3:'总表-2025'!$B$253&'总表-2025'!$C$3:'总表-2025'!$C$253,'总表-2025'!I$3:'总表-2025'!I$253)} | I36: {=_xlfn.XLOOKUP($B$2&$B36,'总表-2025'!$B$3:'总表-2025'!$B$253&'总表-2025'!$C$3:'总表-2025'!$C$253,'总表-2025'!J$3:'总表-2025'!J$253)} | J36: {=_xlfn.XLOOKUP($B$2&$B36,'总表-2025'!$B$3:'总表-2025'!$B$253&'总表-2025'!$C$3:'总表-2025'!$C$253,'总表-2025'!K$3:'总表-2025'!K$253)} | ... O36: {=_xlfn.XLOOKUP($B$2&$B36,'总表-2025'!$B$3:'总表-2025'!$B$253&'总表-2025'!$C$3:'总表-2025'!$C$253,'总表-2025'!P$3:'总表-2025'!P$253)}
A37: 3 | B37: 电度输配电价 | C37: {=_xlfn.XLOOKUP($B$2&$B37,'总表-2025'!$B$3:'总表-2025'!$B$253&'总表-2025'!$C$3:'总表-2025'!$C$253,'总表-2025'!D$3:'总表-2025'!D$253)} | D37: {=_xlfn.XLOOKUP($B$2&$B37,'总表-2025'!$B$3:'总表-2025'!$B$253&'总表-2025'!$C$3:'总表-2025'!$C$253,'总表-2025'!E$3:'总表-2025'!E$253)} | E37: {=_xlfn.XLOOKUP($B$2&$B37,'总表-2025'!$B$3:'总表-2025'!$B$253&'总表-2025'!$C$3:'总表-2025'!$C$253,'总表-2025'!F$3:'总表-2025'!F$253)} | F37: {=_xlfn.XLOOKUP($B$2&$B37,'总表-2025'!$B$3:'总表-2025'!$B$253&'总表-2025'!$C$3:'总表-2025'!$C$253,'总表-2025'!G$3:'总表-2025'!G$253)} | G37: {=_xlfn.XLOOKUP($B$2&$B37,'总表-2025'!$B$3:'总表-2025'!$B$253&'总表-2025'!$C$3:'总表-2025'!$C$253,'总表-2025'!H$3:'总表-2025'!H$253)} | H37: {=_xlfn.XLOOKUP($B$2&$B37,'总表-2025'!$B$3:'总表-2025'!$B$253&'总表-2025'!$C$3:'总表-2025'!$C$253,'总表-2025'!I$3:'总表-2025'!I$253)} | I37: {=_xlfn.XLOOKUP($B$2&$B37,'总表-2025'!$B$3:'总表-2025'!$B$253&'总表-2025'!$C$3:'总表-2025'!$C$253,'总表-2025'!J$3:'总表-2025'!J$253)} | J37: {=_xlfn.XLOOKUP($B$2&$B37,'总表-2025'!$B$3:'总表-2025'!$B$253&'总表-2025'!$C$3:'总表-2025'!$C$253,'总表-2025'!K$3:'总表-2025'!K$253)} | ... O37: {=_xlfn.XLOOKUP($B$2&$B37,'总表-2025'!$B$3:'总表-2025'!$B$253&'总表-2025'!$C$3:'总表-2025'!$C$253,'总表-2025'!P$3:'总表-2025'!P$253)}
A38: 4 | B38: 政府性基金及附加 | C38: {=_xlfn.XLOOKUP($B$2&$B38,'总表-2025'!$B$3:'总表-2025'!$B$253&'总表-2025'!$C$3:'总表-2025'!$C$253,'总表-2025'!D$3:'总表-2025'!D$253)} | D38: {=_xlfn.XLOOKUP($B$2&$B38,'总表-2025'!$B$3:'总表-2025'!$B$253&'总表-2025'!$C$3:'总表-2025'!$C$253,'总表-2025'!E$3:'总表-2025'!E$253)} | E38: {=_xlfn.XLOOKUP($B$2&$B38,'总表-2025'!$B$3:'总表-2025'!$B$253&'总表-2025'!$C$3:'总表-2025'!$C$253,'总表-2025'!F$3:'总表-2025'!F$253)} | F38: {=_xlfn.XLOOKUP($B$2&$B38,'总表-2025'!$B$3:'总表-2025'!$B$253&'总表-2025'!$C$3:'总表-2025'!$C$253,'总表-2025'!G$3:'总表-2025'!G$253)} | G38: {=_xlfn.XLOOKUP($B$2&$B38,'总表-2025'!$B$3:'总表-2025'!$B$253&'总表-2025'!$C$3:'总表-2025'!$C$253,'总表-2025'!H$3:'总表-2025'!H$253)} | H38: {=_xlfn.XLOOKUP($B$2&$B38,'总表-2025'!$B$3:'总表-2025'!$B$253&'总表-2025'!$C$3:'总表-2025'!$C$253,'总表-2025'!I$3:'总表-2025'!I$253)} | I38: {=_xlfn.XLOOKUP($B$2&$B38,'总表-2025'!$B$3:'总表-2025'!$B$253&'总表-2025'!$C$3:'总表-2025'!$C$253,'总表-2025'!J$3:'总表-2025'!J$253)} | J38: {=_xlfn.XLOOKUP($B$2&$B38,'总表-2025'!$B$3:'总表-2025'!$B$253&'总表-2025'!$C$3:'总表-2025'!$C$253,'总表-2025'!K$3:'总表-2025'!K$253)} | ... O38: {=_xlfn.XLOOKUP($B$2&$B38,'总表-2025'!$B$3:'总表-2025'!$B$253&'总表-2025'!$C$3:'总表-2025'!$C$253,'总表-2025'!P$3:'总表-2025'!P$253)}
A39: 5 | B39: 系统运行费折价 | C39: {=_xlfn.XLOOKUP($B$2&$B39,'总表-2025'!$B$3:'总表-2025'!$B$253&'总表-2025'!$C$3:'总表-2025'!$C$253,'总表-2025'!D$3:'总表-2025'!D$253)} | D39: {=_xlfn.XLOOKUP($B$2&$B39,'总表-2025'!$B$3:'总表-2025'!$B$253&'总表-2025'!$C$3:'总表-2025'!$C$253,'总表-2025'!E$3:'总表-2025'!E$253)} | E39: {=_xlfn.XLOOKUP($B$2&$B39,'总表-2025'!$B$3:'总表-2025'!$B$253&'总表-2025'!$C$3:'总表-2025'!$C$253,'总表-2025'!F$3:'总表-2025'!F$253)} | F39: {=_xlfn.XLOOKUP($B$2&$B39,'总表-2025'!$B$3:'总表-2025'!$B$253&'总表-2025'!$C$3:'总表-2025'!$C$253,'总表-2025'!G$3:'总表-2025'!G$253)} | G39: {=_xlfn.XLOOKUP($B$2&$B39,'总表-2025'!$B$3:'总表-2025'!$B$253&'总表-2025'!$C$3:'总表-2025'!$C$253,'总表-2025'!H$3:'总表-2025'!H$253)} | H39: {=_xlfn.XLOOKUP($B$2&$B39,'总表-2025'!$B$3:'总表-2025'!$B$253&'总表-2025'!$C$3:'总表-2025'!$C$253,'总表-2025'!I$3:'总表-2025'!I$253)} | I39: {=_xlfn.XLOOKUP($B$2&$B39,'总表-2025'!$B$3:'总表-2025'!$B$253&'总表-2025'!$C$3:'总表-2025'!$C$253,'总表-2025'!J$3:'总表-2025'!J$253)} | J39: {=_xlfn.XLOOKUP($B$2&$B39,'总表-2025'!$B$3:'总表-2025'!$B$253&'总表-2025'!$C$3:'总表-2025'!$C$253,'总表-2025'!K$3:'总表-2025'!K$253)} | ... O39: {=_xlfn.XLOOKUP($B$2&$B39,'总表-2025'!$B$3:'总表-2025'!$B$253&'总表-2025'!$C$3:'总表-2025'!$C$253,'总表-2025'!P$3:'总表-2025'!P$253)}
A40: 6 | B40: 综合平段电价--电网代购 | C40: {=_xlfn.XLOOKUP($B$2&$B40,'总表-2025'!$B$3:'总表-2025'!$B$253&'总表-2025'!$C$3:'总表-2025'!$C$253,'总表-2025'!D$3:'总表-2025'!D$253)} | D40: {=_xlfn.XLOOKUP($B$2&$B40,'总表-2025'!$B$3:'总表-2025'!$B$253&'总表-2025'!$C$3:'总表-2025'!$C$253,'总表-2025'!E$3:'总表-2025'!E$253)} | E40: {=_xlfn.XLOOKUP($B$2&$B40,'总表-2025'!$B$3:'总表-2025'!$B$253&'总表-2025'!$C$3:'总表-2025'!$C$253,'总表-2025'!F$3:'总表-2025'!F$253)} | F40: {=_xlfn.XLOOKUP($B$2&$B40,'总表-2025'!$B$3:'总表-2025'!$B$253&'总表-2025'!$C$3:'总表-2025'!$C$253,'总表-2025'!G$3:'总表-2025'!G$253)} | G40: {=_xlfn.XLOOKUP($B$2&$B40,'总表-2025'!$B$3:'总表-2025'!$B$253&'总表-2025'!$C$3:'总表-2025'!$C$253,'总表-2025'!H$3:'总表-2025'!H$253)} | H40: {=_xlfn.XLOOKUP($B$2&$B40,'总表-2025'!$B$3:'总表-2025'!$B$253&'总表-2025'!$C$3:'总表-2025'!$C$253,'总表-2025'!I$3:'总表-2025'!I$253)} | I40: {=_xlfn.XLOOKUP($B$2&$B40,'总表-2025'!$B$3:'总表-2025'!$B$253&'总表-2025'!$C$3:'总表-2025'!$C$253,'总表-2025'!J$3:'总表-2025'!J$253)} | J40: {=_xlfn.XLOOKUP($B$2&$B40,'总表-2025'!$B$3:'总表-2025'!$B$253&'总表-2025'!$C$3:'总表-2025'!$C$253,'总表-2025'!K$3:'总表-2025'!K$253)} | ... O40: {=_xlfn.XLOOKUP($B$2&$B40,'总表-2025'!$B$3:'总表-2025'!$B$253&'总表-2025'!$C$3:'总表-2025'!$C$253,'总表-2025'!P$3:'总表-2025'!P$253)}
A41: 7 | B41: 入市交易购电价格 | C41: {=_xlfn.XLOOKUP($B$2&$B41,'总表-2025'!$B$3:'总表-2025'!$B$253&'总表-2025'!$C$3:'总表-2025'!$C$253,'总表-2025'!D$3:'总表-2025'!D$253)} | D41: {=_xlfn.XLOOKUP($B$2&$B41,'总表-2025'!$B$3:'总表-2025'!$B$253&'总表-2025'!$C$3:'总表-2025'!$C$253,'总表-2025'!E$3:'总表-2025'!E$253)} | E41: {=_xlfn.XLOOKUP($B$2&$B41,'总表-2025'!$B$3:'总表-2025'!$B$253&'总表-2025'!$C$3:'总表-2025'!$C$253,'总表-2025'!F$3:'总表-2025'!F$253)} | F41: {=_xlfn.XLOOKUP($B$2&$B41,'总表-2025'!$B$3:'总表-2025'!$B$253&'总表-2025'!$C$3:'总表-2025'!$C$253,'总表-2025'!G$3:'总表-2025'!G$253)} | G41: {=_xlfn.XLOOKUP($B$2&$B41,'总表-2025'!$B$3:'总表-2025'!$B$253&'总表-2025'!$C$3:'总表-2025'!$C$253,'总表-2025'!H$3:'总表-2025'!H$253)} | H41: {=_xlfn.XLOOKUP($B$2&$B41,'总表-2025'!$B$3:'总表-2025'!$B$253&'总表-2025'!$C$3:'总表-2025'!$C$253,'总表-2025'!I$3:'总表-2025'!I$253)} | I41: {=_xlfn.XLOOKUP($B$2&$B41,'总表-2025'!$B$3:'总表-2025'!$B$253&'总表-2025'!$C$3:'总表-2025'!$C$253,'总表-2025'!J$3:'总表-2025'!J$253)} | J41: {=_xlfn.XLOOKUP($B$2&$B41,'总表-2025'!$B$3:'总表-2025'!$B$253&'总表-2025'!$C$3:'总表-2025'!$C$253,'总表-2025'!K$3:'总表-2025'!K$253)} | ... O41: {=_xlfn.XLOOKUP($B$2&$B41,'总表-2025'!$B$3:'总表-2025'!$B$253&'总表-2025'!$C$3:'总表-2025'!$C$253,'总表-2025'!P$3:'总表-2025'!P$253)}
A42: 8 | B42: 综合平段电价--入市交易 | C42: {=_xlfn.XLOOKUP($B$2&$B42,'总表-2025'!$B$3:'总表-2025'!$B$253&'总表-2025'!$C$3:'总表-2025'!$C$253,'总表-2025'!D$3:'总表-2025'!D$253)} | D42: {=_xlfn.XLOOKUP($B$2&$B42,'总表-2025'!$B$3:'总表-2025'!$B$253&'总表-2025'!$C$3:'总表-2025'!$C$253,'总表-2025'!E$3:'总表-2025'!E$253)} | E42: {=_xlfn.XLOOKUP($B$2&$B42,'总表-2025'!$B$3:'总表-2025'!$B$253&'总表-2025'!$C$3:'总表-2025'!$C$253,'总表-2025'!F$3:'总表-2025'!F$253)} | F42: {=_xlfn.XLOOKUP($B$2&$B42,'总表-2025'!$B$3:'总表-2025'!$B$253&'总表-2025'!$C$3:'总表-2025'!$C$253,'总表-2025'!G$3:'总表-2025'!G$253)} | G42: {=_xlfn.XLOOKUP($B$2&$B42,'总表-2025'!$B$3:'总表-2025'!$B$253&'总表-2025'!$C$3:'总表-2025'!$C$253,'总表-2025'!H$3:'总表-2025'!H$253)} | H42: {=_xlfn.XLOOKUP($B$2&$B42,'总表-2025'!$B$3:'总表-2025'!$B$253&'总表-2025'!$C$3:'总表-2025'!$C$253,'总表-2025'!I$3:'总表-2025'!I$253)} | I42: {=_xlfn.XLOOKUP($B$2&$B42,'总表-2025'!$B$3:'总表-2025'!$B$253&'总表-2025'!$C$3:'总表-2025'!$C$253,'总表-2025'!J$3:'总表-2025'!J$253)} | J42: {=_xlfn.XLOOKUP($B$2&$B42,'总表-2025'!$B$3:'总表-2025'!$B$253&'总表-2025'!$C$3:'总表-2025'!$C$253,'总表-2025'!K$3:'总表-2025'!K$253)} | ... O42: {=_xlfn.XLOOKUP($B$2&$B42,'总表-2025'!$B$3:'总表-2025'!$B$253&'总表-2025'!$C$3:'总表-2025'!$C$253,'总表-2025'!P$3:'总表-2025'!P$253)}
A62: 序号 | B62: 作图用表 | C62: 45658 | D62: 45689 | E62: 45717 | F62: 45748 | G62: 45778 | H62: 45809 | I62: 45839 | J62: 45870 | K62: 45901 | L62: 45931 | M62: 45962 | N62: 45992 | O62: 46023 | P62: 46054 | Q62: 46082 | R62: 46113 | S62: 46143 | T62: 46174 | U62: 46204 | V62: 46235 | W62: 46266 | X62: 46296 | Y62: 46327 | Z62: 46357
A63: 1 | B63: 代理购电价格 Y2025 | C63: =C35 | D63: =D35 | E63: =E35 | F63: =F35 | G63: =G35 | H63: =H35 | I63: =I35 | J63: =J35 | ... N63: =N35 | O63: =O64
A64: 1 | B64: 代理购电价格 Y2026 | O64: =C7 | P64: =D7 | Q64: =E7 | R64: =F7 | S64: =G7 | T64: =H7 | U64: =I7 | V64: =J7 | ... Z64: =N7
A65: 2 | B65: 综合平段电价--电网代购 Y2025 | C65: =C40 | D65: =D40 | E65: =E40 | F65: =F40 | G65: =G40 | H65: =H40 | I65: =I40 | J65: =J40 | ... N65: =N40 | O65: =O66
A66: 2 | B66: 综合平段电价--电网代购 Y2026 | O66: =C12 | P66: =D12 | Q66: =E12 | R66: =F12 | S66: =G12 | T66: =H12 | U66: =I12 | V66: =J12 | ... Z66: =N12
A67: 3 | B67: 上网环节线损电价 Y2025 | C67: =C36 | D67: =D36 | E67: =E36 | F67: =F36 | G67: =G36 | H67: =H36 | I67: =I36 | J67: =J36 | ... N67: =N36 | O67: =C8
A68: 3 | B68: 上网环节线损电价 Y2026 | O68: =C8 | P68: =D8 | Q68: =E8 | R68: =F8 | S68: =G8 | T68: =H8 | U68: =I8 | V68: =J8 | ... Z68: =N8
A69: 4 | B69: 系统运行费折价 Y2025 | C69: =C39 | D69: =D39 | E69: =E39 | F69: =F39 | G69: =G39 | H69: =H39 | I69: =I39 | J69: =J39 | ... N69: =N39 | O69: =C11
A70: 4 | B70: 系统运行费折价 Y2026 | O70: =C11 | P70: =D11 | Q70: =E11 | R70: =F11 | S70: =G11 | T70: =H11 | U70: =I11 | V70: =J11 | ... Z70: =N11
B75: 省间电价对比
A76: 电压等级 | B76: 两部制220kV
A77: 省份1 | B77: 冀北
A78: 省份2 | B78: 江苏
A79: 省份3 | B79: 天津
A80: 省份4 | B80: 蒙西
A81: 省份5 | B81: 上海
A101: 序号 | B101: 综合平段--电网代购价 | C101: 45658 | D101: 45689 | E101: 45717 | F101: 45748 | G101: 45778 | H101: 45809 | I101: 45839 | J101: 45870 | K101: 45901 | L101: 45931 | M101: 45962 | N101: 45992 | O101: 46023 | P101: 46054 | Q101: 46082 | R101: 46113 | S101: 46143 | T101: 46174 | U101: 46204 | V101: 46235 | W101: 46266 | X101: 46296 | Y101: 46327 | Z101: 46357
...

Sheet 总表-2026
B1: 电压等级 | C1: ='首页+选择功能'!B4
A2: 序号 | B2: 省份 | C2: 2026年电价表 | D2: 1月 | E2: 2月 | F2: 3月 | G2: 4月 | H2: 5月 | I2: 6月 | J2: 7月 | K2: 8月 | L2: 9月 | M2: 10月 | N2: 11月 | O2: 12月 | P2: 年均 | Q2: 趋势图
A3: 1 | B3: 北京 | C3: 代理购电价格 | D3: ='分表1-2026电网代购价'!D2 | E3: ='分表1-2026电网代购价'!E2 | F3: ='分表1-2026电网代购价'!F2 | G3: ='分表1-2026电网代购价'!G2 | H3: ='分表1-2026电网代购价'!H2 | P3: =IF(SUM(D3:O3)=0,"0",AVERAGEIF(D3:O3,"<>0",D3:O3))
A4: 2 | B4: 北京 | C4: 上网环节线损电价 | D4: ='分表2-2026上网环节线损'!C2 | E4: ='分表2-2026上网环节线损'!D2 | F4: ='分表2-2026上网环节线损'!E2 | G4: ='分表2-2026上网环节线损'!F2 | H4: ='分表2-2026上网环节线损'!G2 | P4: =IF(SUM(D4:O4)=0,"0",AVERAGEIF(D4:O4,"<>0",D4:O4))
A5: 3 | B5: 北京 | C5: 电度输配电价 | D5: {=_xlfn.XLOOKUP($C$1,'分表4-电度输配电价'!$C2：'分表4-电度输配电价'!$C9&'分表4-电度输配电价'!$D2：'分表4-电度输配电价'!$D9,'分表4-电度输配电价'!$E2：'分表4-电度输配电价'!$E9)} | E5: {=_xlfn.XLOOKUP($C$1,'分表4-电度输配电价'!$C2：'分表4-电度输配电价'!$C9&'分表4-电度输配电价'!$D2：'分表4-电度输配电价'!$D9,'分表4-电度输配电价'!$E2：'分表4-电度输配电价'!$E9)} | F5: {=_xlfn.XLOOKUP($C$1,'分表4-电度输配电价'!$C2：'分表4-电度输配电价'!$C9&'分表4-电度输配电价'!$D2：'分表4-电度输配电价'!$D9,'分表4-电度输配电价'!$E2：'分表4-电度输配电价'!$E9)} | G5: {=_xlfn.XLOOKUP($C$1,'分表4-电度输配电价'!$C2：'分表4-电度输配电价'!$C9&'分表4-电度输配电价'!$D2：'分表4-电度输配电价'!$D9,'分表4-电度输配电价'!$E2：'分表4-电度输配电价'!$E9)} | H5: {=_xlfn.XLOOKUP($C$1,'分表4-电度输配电价'!$C2：'分表4-电度输配电价'!$C9&'分表4-电度输配电价'!$D2：'分表4-电度输配电价'!$D9,'分表4-电度输配电价'!$E2：'分表4-电度输配电价'!$E9)} | P5: =IF(SUM(D5:O5)=0,"0",AVERAGEIF(D5:O5,"<>0",D5:O5))
A6: 4 | B6: 北京 | C6: 政府性基金及附加 | D6: {=_xlfn.XLOOKUP($B$6,'分表5-政府性基金及附加'!$B$2：'分表5-政府性基金及附加'!$B$199,'分表5-政府性基金及附加'!$D$2：'分表5-政府性基金及附加'!$D$199)} | E6: {=_xlfn.XLOOKUP($B$6,'分表5-政府性基金及附加'!$B$2：'分表5-政府性基金及附加'!$B$199,'分表5-政府性基金及附加'!$D$2：'分表5-政府性基金及附加'!$D$199)} | F6: {=_xlfn.XLOOKUP($B$6,'分表5-政府性基金及附加'!$B$2：'分表5-政府性基金及附加'!$B$199,'分表5-政府性基金及附加'!$D$2：'分表5-政府性基金及附加'!$D$199)} | G6: {=_xlfn.XLOOKUP($B$6,'分表5-政府性基金及附加'!$B$2：'分表5-政府性基金及附加'!$B$199,'分表5-政府性基金及附加'!$D$2：'分表5-政府性基金及附加'!$D$199)} | H6: {=_xlfn.XLOOKUP($B$6,'分表5-政府性基金及附加'!$B$2：'分表5-政府性基金及附加'!$B$199,'分表5-政府性基金及附加'!$D$2：'分表5-政府性基金及附加'!$D$199)} | P6: =IF(SUM(D6:O6)=0,"0",AVERAGEIF(D6:O6,"<>0",D6:O6))
A7: 5 | B7: 北京 | C7: 系统运行费折价 | D7: ='分表3-2026系统运行费'!D2 | E7: ='分表3-2026系统运行费'!E2 | F7: ='分表3-2026系统运行费'!F2 | G7: ='分表3-2026系统运行费'!G2 | H7: ='分表3-2026系统运行费'!H2 | P7: =IF(SUM(D7:O7)=0,"0",AVERAGEIF(D7:O7,"<>0",D7:O7))
A8: 6 | B8: 北京 | C8: 综合平段电价--电网代购 | D8: =IF(D5="/","/",SUM(D3:D7)) | E8: =IF(E5="/","/",SUM(E3:E7)) | F8: =IF(F5="/","/",SUM(F3:F7)) | G8: =IF(G5="/","/",SUM(G3:G7)) | H8: =IF(H5="/","/",SUM(H3:H7)) | P8: =IF(SUM(D8:O8)=0,"0",AVERAGEIF(D8:O8,"<>0",D8:O8))
A9: 7 | B9: 北京 | C9: 入市交易购电价格 | D9: ='分表7-2026交易价格'!D2 | E9: ='分表7-2026交易价格'!E2 | F9: ='分表7-2026交易价格'!F2 | G9: ='分表7-2026交易价格'!G2 | H9: ='分表7-2026交易价格'!H2 | P9: =IF(SUM(D9:O9)=0,"0",AVERAGEIF(D9:O9,"<>0",D9:O9))
A10: 8 | B10: 北京 | C10: 综合平段电价--入市交易 | D10: =IF(D5="/","/",IF(D9>0,D9+SUM(D4:D7),"/")) | E10: =IF(E5="/","/",IF(E9>0,E9+SUM(E4:E7),"/")) | F10: =IF(F5="/","/",IF(F9>0,F9+SUM(F4:F7),"/")) | G10: =IF(G5="/","/",IF(G9>0,G9+SUM(G4:G7),"/")) | H10: =IF(H5="/","/",IF(H9>0,H9+SUM(H4:H7),"/")) | P10: =IF(SUM(D10:O10)=0,"0",AVERAGEIF(D10:O10,"<>0",D10:O10))
A11: 9 | B11: 天津 | C11: 代理购电价格 | D11: ='分表1-2026电网代购价'!D5 | E11: ='分表1-2026电网代购价'!E5 | F11: ='分表1-2026电网代购价'!F5 | G11: ='分表1-2026电网代购价'!G5 | H11: ='分表1-2026电网代购价'!H5 | P11: =IF(SUM(D11:O11)=0,"0",AVERAGEIF(D11:O11,"<>0",D11:O11))
A12: 10 | B12: 天津 | C12: 上网环节线损电价 | D12: ='分表2-2026上网环节线损'!C3 | E12: ='分表2-2026上网环节线损'!D3 | F12: ='分表2-2026上网环节线损'!E3 | G12: ='分表2-2026上网环节线损'!F3 | H12: ='分表2-2026上网环节线损'!G3 | P12: =IF(SUM(D12:O12)=0,"0",AVERAGEIF(D12:O12,"<>0",D12:O12))
A13: 11 | B13: 天津 | C13: 电度输配电价 | D13: {=_xlfn.XLOOKUP($C$1,'分表4-电度输配电价'!$C10：'分表4-电度输配电价'!$C17&'分表4-电度输配电价'!$D10：'分表4-电度输配电价'!$D17,'分表4-电度输配电价'!$E10：'分表4-电度输配电价'!$E17)} | E13: {=_xlfn.XLOOKUP($C$1,'分表4-电度输配电价'!$C10：'分表4-电度输配电价'!$C17&'分表4-电度输配电价'!$D10：'分表4-电度输配电价'!$D17,'分表4-电度输配电价'!$E10：'分表4-电度输配电价'!$E17)} | F13: {=_xlfn.XLOOKUP($C$1,'分表4-电度输配电价'!$C10：'分表4-电度输配电价'!$C17&'分表4-电度输配电价'!$D10：'分表4-电度输配电价'!$D17,'分表4-电度输配电价'!$E10：'分表4-电度输配电价'!$E17)} | G13: {=_xlfn.XLOOKUP($C$1,'分表4-电度输配电价'!$C10：'分表4-电度输配电价'!$C17&'分表4-电度输配电价'!$D10：'分表4-电度输配电价'!$D17,'分表4-电度输配电价'!$E10：'分表4-电度输配电价'!$E17)} | H13: {=_xlfn.XLOOKUP($C$1,'分表4-电度输配电价'!$C10：'分表4-电度输配电价'!$C17&'分表4-电度输配电价'!$D10：'分表4-电度输配电价'!$D17,'分表4-电度输配电价'!$E10：'分表4-电度输配电价'!$E17)} | P13: =IF(SUM(D13:O13)=0,"0",AVERAGEIF(D13:O13,"<>0",D13:O13))
A14: 12 | B14: 天津 | C14: 政府性基金及附加 | D14: {=_xlfn.XLOOKUP($B$14,'分表5-政府性基金及附加'!$B$2：'分表5-政府性基金及附加'!$B$199,'分表5-政府性基金及附加'!$D$2：'分表5-政府性基金及附加'!$D$199)} | E14: {=_xlfn.XLOOKUP($B$14,'分表5-政府性基金及附加'!$B$2：'分表5-政府性基金及附加'!$B$199,'分表5-政府性基金及附加'!$D$2：'分表5-政府性基金及附加'!$D$199)} | F14: {=_xlfn.XLOOKUP($B$14,'分表5-政府性基金及附加'!$B$2：'分表5-政府性基金及附加'!$B$199,'分表5-政府性基金及附加'!$D$2：'分表5-政府性基金及附加'!$D$199)} | G14: {=_xlfn.XLOOKUP($B$14,'分表5-政府性基金及附加'!$B$2：'分表5-政府性基金及附加'!$B$199,'分表5-政府性基金及附加'!$D$2：'分表5-政府性基金及附加'!$D$199)} | H14: {=_xlfn.XLOOKUP($B$14,'分表5-政府性基金及附加'!$B$2：'分表5-政府性基金及附加'!$B$199,'分表5-政府性基金及附加'!$D$2：'分表5-政府性基金及附加'!$D$199)} | P14: =IF(SUM(D14:O14)=0,"0",AVERAGEIF(D14:O14,"<>0",D14:O14))
A15: 13 | B15: 天津 | C15: 系统运行费折价 | D15: ='分表3-2026系统运行费'!Q2 | E15: ='分表3-2026系统运行费'!R2 | F15: ='分表3-2026系统运行费'!S2 | G15: ='分表3-2026系统运行费'!T2 | H15: ='分表3-2026系统运行费'!U2 | P15: =IF(SUM(D15:O15)=0,"0",AVERAGEIF(D15:O15,"<>0",D15:O15))
A16: 14 | B16: 天津 | C16: 综合平段电价--电网代购 | D16: =IF(D13="/","/",SUM(D11:D15)) | E16: =IF(E13="/","/",SUM(E11:E15)) | F16: =IF(F13="/","/",SUM(F11:F15)) | G16: =IF(G13="/","/",SUM(G11:G15)) | H16: =IF(H13="/","/",SUM(H11:H15)) | P16: =IF(SUM(D16:O16)=0,"0",AVERAGEIF(D16:O16,"<>0",D16:O16))
A17: 15 | B17: 天津 | C17: 入市交易购电价格 | D17: ='分表7-2026交易价格'!D3 | E17: ='分表7-2026交易价格'!E3 | F17: ='分表7-2026交易价格'!F3 | G17: ='分表7-2026交易价格'!G3 | H17: ='分表7-2026交易价格'!H3 | P17: =IF(SUM(D17:O17)=0,"0",AVERAGEIF(D17:O17,"<>0",D17:O17))
A18: 16 | B18: 天津 | C18: 综合平段电价--入市交易 | D18: =IF(D13="/","/",IF(D17>0,D17+SUM(D12:D15),"/")) | E18: =IF(E13="/","/",IF(E17>0,E17+SUM(E12:E15),"/")) | F18: =IF(F13="/","/",IF(F17>0,F17+SUM(F12:F15),"/")) | G18: =IF(G13="/","/",IF(G17>0,G17+SUM(G12:G15),"/")) | H18: =IF(H13="/","/",IF(H17>0,H17+SUM(H12:H15),"/")) | P18: =IF(SUM(D18:O18)=0,"0",AVERAGEIF(D18:O18,"<>0",D18:O18))
A19: 17 | B19: 河北南网 | C19: 代理购电价格 | D19: ='分表1-2026电网代购价'!D8 | E19: ='分表1-2026电网代购价'!E8 | F19: ='分表1-2026电网代购价'!F8 | G19: ='分表1-2026电网代购价'!G8 | H19: ='分表1-2026电网代购价'!H8 | P19: =IF(SUM(D19:O19)=0,"0",AVERAGEIF(D19:O19,"<>0",D19:O19))
A20: 18 | B20: 河北南网 | C20: 上网环节线损电价 | D20: ='分表2-2026上网环节线损'!C4 | E20: ='分表2-2026上网环节线损'!D4 | F20: ='分表2-2026上网环节线损'!E4 | G20: ='分表2-2026上网环节线损'!F4 | H20: ='分表2-2026上网环节线损'!G4 | P20: =IF(SUM(D20:O20)=0,"0",AVERAGEIF(D20:O20,"<>0",D20:O20))
A21: 19 | B21: 河北南网 | C21: 电度输配电价 | D21: {=_xlfn.XLOOKUP($C$1,'分表4-电度输配电价'!$C18：'分表4-电度输配电价'!$C25&'分表4-电度输配电价'!$D18：'分表4-电度输配电价'!$D25,'分表4-电度输配电价'!$E18：'分表4-电度输配电价'!$E25)} | E21: {=_xlfn.XLOOKUP($C$1,'分表4-电度输配电价'!$C18：'分表4-电度输配电价'!$C25&'分表4-电度输配电价'!$D18：'分表4-电度输配电价'!$D25,'分表4-电度输配电价'!$E18：'分表4-电度输配电价'!$E25)} | F21: {=_xlfn.XLOOKUP($C$1,'分表4-电度输配电价'!$C18：'分表4-电度输配电价'!$C25&'分表4-电度输配电价'!$D18：'分表4-电度输配电价'!$D25,'分表4-电度输配电价'!$E18：'分表4-电度输配电价'!$E25)} | G21: {=_xlfn.XLOOKUP($C$1,'分表4-电度输配电价'!$C18：'分表4-电度输配电价'!$C25&'分表4-电度输配电价'!$D18：'分表4-电度输配电价'!$D25,'分表4-电度输配电价'!$E18：'分表4-电度输配电价'!$E25)} | H21: {=_xlfn.XLOOKUP($C$1,'分表4-电度输配电价'!$C18：'分表4-电度输配电价'!$C25&'分表4-电度输配电价'!$D18：'分表4-电度输配电价'!$D25,'分表4-电度输配电价'!$E18：'分表4-电度输配电价'!$E25)} | P21: =IF(SUM(D21:O21)=0,"0",AVERAGEIF(D21:O21,"<>0",D21:O21))
A22: 20 | B22: 河北南网 | C22: 政府性基金及附加 | D22: {=_xlfn.XLOOKUP($B$22,'分表5-政府性基金及附加'!$B$2：'分表5-政府性基金及附加'!$B$199,'分表5-政府性基金及附加'!$D$2：'分表5-政府性基金及附加'!$D$199)} | E22: {=_xlfn.XLOOKUP($B$22,'分表5-政府性基金及附加'!$B$2：'分表5-政府性基金及附加'!$B$199,'分表5-政府性基金及附加'!$D$2：'分表5-政府性基金及附加'!$D$199)} | F22: {=_xlfn.XLOOKUP($B$22,'分表5-政府性基金及附加'!$B$2：'分表5-政府性基金及附加'!$B$199,'分表5-政府性基金及附加'!$D$2：'分表5-政府性基金及附加'!$D$199)} | G22: {=_xlfn.XLOOKUP($B$22,'分表5-政府性基金及附加'!$B$2：'分表5-政府性基金及附加'!$B$199,'分表5-政府性基金及附加'!$D$2：'分表5-政府性基金及附加'!$D$199)} | H22: {=_xlfn.XLOOKUP($B$22,'分表5-政府性基金及附加'!$B$2：'分表5-政府性基金及附加'!$B$199,'分表5-政府性基金及附加'!$D$2：'分表5-政府性基金及附加'!$D$199)} | P22: =IF(SUM(D22:O22)=0,"0",AVERAGEIF(D22:O22,"<>0",D22:O22))
A23: 21 | B23: 河北南网 | C23: 系统运行费折价 | D23: ='分表3-2026系统运行费'!AD2 | E23: ='分表3-2026系统运行费'!AE2 | F23: ='分表3-2026系统运行费'!AF2 | G23: ='分表3-2026系统运行费'!AG2 | H23: ='分表3-2026系统运行费'!AH2 | P23: =IF(SUM(D23:O23)=0,"0",AVERAGEIF(D23:O23,"<>0",D23:O23))
A24: 22 | B24: 河北南网 | C24: 综合平段电价--电网代购 | D24: =IF(D21="/","/",SUM(D19:D23)) | E24: =IF(E21="/","/",SUM(E19:E23)) | F24: =IF(F21="/","/",SUM(F19:F23)) | G24: =IF(G21="/","/",SUM(G19:G23)) | H24: =IF(H21="/","/",SUM(H19:H23)) | P24: =IF(SUM(D24:O24)=0,"0",AVERAGEIF(D24:O24,"<>0",D24:O24))
A25: 23 | B25: 河北南网 | C25: 入市交易购电价格 | D25: ='分表7-2026交易价格'!D4 | E25: ='分表7-2026交易价格'!E4 | F25: ='分表7-2026交易价格'!F4 | G25: ='分表7-2026交易价格'!G4 | H25: ='分表7-2026交易价格'!H4 | P25: =IF(SUM(D25:O25)=0,"0",AVERAGEIF(D25:O25,"<>0",D25:O25))
A26: 24 | B26: 河北南网 | C26: 综合平段电价--入市交易 | D26: =IF(D21="/","/",IF(D25>0,D25+SUM(D20:D23),"/")) | E26: =IF(E21="/","/",IF(E25>0,E25+SUM(E20:E23),"/")) | F26: =IF(F21="/","/",IF(F25>0,F25+SUM(F20:F23),"/")) | G26: =IF(G21="/","/",IF(G25>0,G25+SUM(G20:G23),"/")) | H26: =IF(H21="/","/",IF(H25>0,H25+SUM(H20:H23),"/")) | P26: =IF(SUM(D26:O26)=0,"0",AVERAGEIF(D26:O26,"<>0",D26:O26))
A27: 25 | B27: 冀北 | C27: 代理购电价格 | D27: ='分表1-2026电网代购价'!D11 | E27: ='分表1-2026电网代购价'!E11 | F27: ='分表1-2026电网代购价'!F11 | G27: ='分表1-2026电网代购价'!G11 | H27: ='分表1-2026电网代购价'!H11 | P27: =IF(SUM(D27:O27)=0,"0",AVERAGEIF(D27:O27,"<>0",D27:O27))
A28: 26 | B28: 冀北 | C28: 上网环节线损电价 | D28: ='分表2-2026上网环节线损'!C5 | E28: ='分表2-2026上网环节线损'!D5 | F28: ='分表2-2026上网环节线损'!E5 | G28: ='分表2-2026上网环节线损'!F5 | H28: ='分表2-2026上网环节线损'!G5 | P28: =IF(SUM(D28:O28)=0,"0",AVERAGEIF(D28:O28,"<>0",D28:O28))
A29: 27 | B29: 冀北 | C29: 电度输配电价 | D29: {=_xlfn.XLOOKUP($C$1,'分表4-电度输配电价'!$C26：'分表4-电度输配电价'!$C33&'分表4-电度输配电价'!$D26：'分表4-电度输配电价'!$D33,'分表4-电度输配电价'!$E26：'分表4-电度输配电价'!$E33)} | E29: {=_xlfn.XLOOKUP($C$1,'分表4-电度输配电价'!$C26：'分表4-电度输配电价'!$C33&'分表4-电度输配电价'!$D26：'分表4-电度输配电价'!$D33,'分表4-电度输配电价'!$E26：'分表4-电度输配电价'!$E33)} | F29: {=_xlfn.XLOOKUP($C$1,'分表4-电度输配电价'!$C26：'分表4-电度输配电价'!$C33&'分表4-电度输配电价'!$D26：'分表4-电度输配电价'!$D33,'分表4-电度输配电价'!$E26：'分表4-电度输配电价'!$E33)} | G29: {=_xlfn.XLOOKUP($C$1,'分表4-电度输配电价'!$C26：'分表4-电度输配电价'!$C33&'分表4-电度输配电价'!$D26：'分表4-电度输配电价'!$D33,'分表4-电度输配电价'!$E26：'分表4-电度输配电价'!$E33)} | H29: {=_xlfn.XLOOKUP($C$1,'分表4-电度输配电价'!$C26：'分表4-电度输配电价'!$C33&'分表4-电度输配电价'!$D26：'分表4-电度输配电价'!$D33,'分表4-电度输配电价'!$E26：'分表4-电度输配电价'!$E33)} | P29: =IF(SUM(D29:O29)=0,"0",AVERAGEIF(D29:O29,"<>0",D29:O29))
A30: 28 | B30: 冀北 | C30: 政府性基金及附加 | D30: {=_xlfn.XLOOKUP($B$30,'分表5-政府性基金及附加'!$B$2：'分表5-政府性基金及附加'!$B$199,'分表5-政府性基金及附加'!$D$2：'分表5-政府性基金及附加'!$D$199)} | E30: {=_xlfn.XLOOKUP($B$30,'分表5-政府性基金及附加'!$B$2：'分表5-政府性基金及附加'!$B$199,'分表5-政府性基金及附加'!$D$2：'分表5-政府性基金及附加'!$D$199)} | F30: {=_xlfn.XLOOKUP($B$30,'分表5-政府性基金及附加'!$B$2：'分表5-政府性基金及附加'!$B$199,'分表5-政府性基金及附加'!$D$2：'分表5-政府性基金及附加'!$D$199)} | G30: {=_xlfn.XLOOKUP($B$30,'分表5-政府性基金及附加'!$B$2：'分表5-政府性基金及附加'!$B$199,'分表5-政府性基金及附加'!$D$2：'分表5-政府性基金及附加'!$D$199)} | H30: {=_xlfn.XLOOKUP($B$30,'分表5-政府性基金及附加'!$B$2：'分表5-政府性基金及附加'!$B$199,'分表5-政府性基金及附加'!$D$2：'分表5-政府性基金及附加'!$D$199)} | P30: =IF(SUM(D30:O30)=0,"0",AVERAGEIF(D30:O30,"<>0",D30:O30))
A31: 29 | B31: 冀北 | C31: 系统运行费折价 | D31: ='分表3-2026系统运行费'!AQ2 | E31: ='分表3-2026系统运行费'!AR2 | F31: ='分表3-2026系统运行费'!AS2 | G31: ='分表3-2026系统运行费'!AT2 | H31: ='分表3-2026系统运行费'!AU2 | P31: =IF(SUM(D31:O31)=0,"0",AVERAGEIF(D31:O31,"<>0",D31:O31))
A32: 30 | B32: 冀北 | C32: 综合平段电价--电网代购 | D32: =IF(D29="/","/",SUM(D27:D31)) | E32: =IF(E29="/","/",SUM(E27:E31)) | F32: =IF(F29="/","/",SUM(F27:F31)) | G32: =IF(G29="/","/",SUM(G27:G31)) | H32: =IF(H29="/","/",SUM(H27:H31)) | P32: =IF(SUM(D32:O32)=0,"0",AVERAGEIF(D32:O32,"<>0",D32:O32))
A33: 31 | B33: 冀北 | C33: 入市交易购电价格 | D33: ='分表7-2026交易价格'!D5 | E33: ='分表7-2026交易价格'!E5 | F33: ='分表7-2026交易价格'!F5 | G33: ='分表7-2026交易价格'!G5 | H33: ='分表7-2026交易价格'!H5 | P33: =IF(SUM(D33:O33)=0,"0",AVERAGEIF(D33:O33,"<>0",D33:O33))
A34: 32 | B34: 冀北 | C34: 综合平段电价--入市交易 | D34: =IF(D29="/","/",IF(D33>0,D33+SUM(D28:D31),"/")) | E34: =IF(E29="/","/",IF(E33>0,E33+SUM(E28:E31),"/")) | F34: =IF(F29="/","/",IF(F33>0,F33+SUM(F28:F31),"/")) | G34: =IF(G29="/","/",IF(G33>0,G33+SUM(G28:G31),"/")) | H34: =IF(H29="/","/",IF(H33>0,H33+SUM(H28:H31),"/")) | P34: =IF(SUM(D34:O34)=0,"0",AVERAGEIF(D34:O34,"<>0",D34:O34))
A35: 33 | B35: 山东 | C35: 代理购电价格 | D35: ='分表1-2026电网代购价'!D14 | E35: ='分表1-2026电网代购价'!E14 | F35: ='分表1-2026电网代购价'!F14 | G35: ='分表1-2026电网代购价'!G14 | H35: ='分表1-2026电网代购价'!H14 | P35: =IF(SUM(D35:O35)=0,"0",AVERAGEIF(D35:O35,"<>0",D35:O35))
A36: 34 | B36: 山东 | C36: 上网环节线损电价 | D36: ='分表2-2026上网环节线损'!C6 | E36: ='分表2-2026上网环节线损'!D6 | F36: ='分表2-2026上网环节线损'!E6 | G36: ='分表2-2026上网环节线损'!F6 | H36: ='分表2-2026上网环节线损'!G6 | P36: =IF(SUM(D36:O36)=0,"0",AVERAGEIF(D36:O36,"<>0",D36:O36))
A37: 35 | B37: 山东 | C37: 电度输配电价 | D37: {=_xlfn.XLOOKUP($C$1,'分表4-电度输配电价'!$C34：'分表4-电度输配电价'!$C41&'分表4-电度输配电价'!$D34：'分表4-电度输配电价'!$D41,'分表4-电度输配电价'!$E34：'分表4-电度输配电价'!$E41)} | E37: {=_xlfn.XLOOKUP($C$1,'分表4-电度输配电价'!$C34：'分表4-电度输配电价'!$C41&'分表4-电度输配电价'!$D34：'分表4-电度输配电价'!$D41,'分表4-电度输配电价'!$E34：'分表4-电度输配电价'!$E41)} | F37: {=_xlfn.XLOOKUP($C$1,'分表4-电度输配电价'!$C34：'分表4-电度输配电价'!$C41&'分表4-电度输配电价'!$D34：'分表4-电度输配电价'!$D41,'分表4-电度输配电价'!$E34：'分表4-电度输配电价'!$E41)} | G37: {=_xlfn.XLOOKUP($C$1,'分表4-电度输配电价'!$C34：'分表4-电度输配电价'!$C41&'分表4-电度输配电价'!$D34：'分表4-电度输配电价'!$D41,'分表4-电度输配电价'!$E34：'分表4-电度输配电价'!$E41)} | H37: {=_xlfn.XLOOKUP($C$1,'分表4-电度输配电价'!$C34：'分表4-电度输配电价'!$C41&'分表4-电度输配电价'!$D34：'分表4-电度输配电价'!$D41,'分表4-电度输配电价'!$E34：'分表4-电度输配电价'!$E41)} | P37: =IF(SUM(D37:O37)=0,"0",AVERAGEIF(D37:O37,"<>0",D37:O37))
A38: 36 | B38: 山东 | C38: 政府性基金及附加 | D38: {=_xlfn.XLOOKUP($B$38,'分表5-政府性基金及附加'!$B$2：'分表5-政府性基金及附加'!$B$199,'分表5-政府性基金及附加'!$D$2：'分表5-政府性基金及附加'!$D$199)} | E38: {=_xlfn.XLOOKUP($B$38,'分表5-政府性基金及附加'!$B$2：'分表5-政府性基金及附加'!$B$199,'分表5-政府性基金及附加'!$D$2：'分表5-政府性基金及附加'!$D$199)} | F38: {=_xlfn.XLOOKUP($B$38,'分表5-政府性基金及附加'!$B$2：'分表5-政府性基金及附加'!$B$199,'分表5-政府性基金及附加'!$D$2：'分表5-政府性基金及附加'!$D$199)} | G38: {=_xlfn.XLOOKUP($B$38,'分表5-政府性基金及附加'!$B$2：'分表5-政府性基金及附加'!$B$199,'分表5-政府性基金及附加'!$D$2：'分表5-政府性基金及附加'!$D$199)} | H38: {=_xlfn.XLOOKUP($B$38,'分表5-政府性基金及附加'!$B$2：'分表5-政府性基金及附加'!$B$199,'分表5-政府性基金及附加'!$D$2：'分表5-政府性基金及附加'!$D$199)} | P38: =IF(SUM(D38:O38)=0,"0",AVERAGEIF(D38:O38,"<>0",D38:O38))
A39: 37 | B39: 山东 | C39: 系统运行费折价 | D39: ='分表3-2026系统运行费'!BD2 | E39: ='分表3-2026系统运行费'!BE2 | F39: ='分表3-2026系统运行费'!BF2 | G39: ='分表3-2026系统运行费'!BG2 | H39: ='分表3-2026系统运行费'!BH2 | P39: =IF(SUM(D39:O39)=0,"0",AVERAGEIF(D39:O39,"<>0",D39:O39))
A40: 38 | B40: 山东 | C40: 综合平段电价--电网代购 | D40: =IF(D37="/","/",SUM(D35:D39)) | E40: =IF(E37="/","/",SUM(E35:E39)) | F40: =IF(F37="/","/",SUM(F35:F39)) | G40: =IF(G37="/","/",SUM(G35:G39)) | H40: =IF(H37="/","/",SUM(H35:H39)) | P40: =IF(SUM(D40:O40)=0,"0",AVERAGEIF(D40:O40,"<>0",D40:O40))
...

Sheet 分表1-2026电网代购价
A1: 序号 | B1: 2026年代理购电价格 | C1: 省份 | D1: 1月 | E1: 2月 | F1: 3月 | G1: 4月 | H1: 5月 | I1: 6月 | J1: 7月 | K1: 8月 | L1: 9月 | M1: 10月 | N1: 11月 | O1: 12月 | P1: 年均 | Q1: 趋势图
A2: 1 | B2: 代理工商业购电价格 | C2: 北京 | D2: =D3+D4 | E2: =E3+E4 | F2: =F3+F4 | G2: =G3+G4 | H2: =H3+H4 | I2: =I3+I4 | J2: =J3+J4 | K2: =K3+K4 | ... O2: =O3+O4 | P2: =IF(SUM(D2:O2)=0,"0",AVERAGEIF(D2:O2,"<>0",D2:O2))
A3: 2 | B3: （1）当月平均购电价格 | C3: 北京 | D3: 0.387359 | E3: 0.386753 | F3: 0.388485 | G3: 0.389043 | H3: 0.387025 | P3: =IF(SUM(D3:O3)=0,"0",AVERAGEIF(D3:O3,"<>0",D3:O3))
A4: 3 | B4: （2）历史偏差电费折价 | C4: 北京 | D4: -0.004021 | E4: -0.005949 | F4: 0.000221 | G4: -0.005019 | H4: 0.011688 | P4: =IF(SUM(D4:O4)=0,"0",AVERAGEIF(D4:O4,"<>0",D4:O4))
A5: 4 | B5: 代理工商业购电价格 | C5: 天津 | D5: =D6+D7 | E5: =E6+E7 | F5: =F6+F7 | G5: =G6+G7 | H5: =H6+H7 | I5: =I6+I7 | J5: =J6+J7 | K5: =K6+K7 | ... O5: =O6+O7 | P5: =IF(SUM(D5:O5)=0,"0",AVERAGEIF(D5:O5,"<>0",D5:O5))
A6: 5 | B6: （1）当月平均购电价格 | C6: 天津 | D6: 0.383083 | E6: 0.382515 | F6: 0.382257 | G6: 0.386076 | H6: 0.383864 | P6: =IF(SUM(D6:O6)=0,"0",AVERAGEIF(D6:O6,"<>0",D6:O6))
A7: 6 | B7: （2）历史偏差电费折价 | C7: 天津 | D7: -0.016602 | E7: 0.012244 | F7: 0.011614 | G7: 0.008519 | H7: 0.004914 | P7: =IF(SUM(D7:O7)=0,"0",AVERAGEIF(D7:O7,"<>0",D7:O7))
A8: 7 | B8: 代理工商业购电价格 | C8: 河北南网 | D8: =D9+D10 | E8: =E9+E10 | F8: =F9+F10 | G8: =G9+G10 | H8: =H9+H10 | I8: =I9+I10 | J8: =J9+J10 | K8: =K9+K10 | ... O8: =O9+O10 | P8: =IF(SUM(D8:O8)=0,"0",AVERAGEIF(D8:O8,"<>0",D8:O8))
A9: 8 | B9: （1）当月平均购电价格 | C9: 河北南网 | D9: 0.40765 | E9: 0.403833 | F9: 0.39112 | G9: 0.383888 | H9: 0.377996 | P9: =IF(SUM(D9:O9)=0,"0",AVERAGEIF(D9:O9,"<>0",D9:O9))
A10: 9 | B10: （2）历史偏差电费折价 | C10: 河北南网 | D10: 0.016791 | E10: 0.007077 | F10: 0.006872 | G10: 0.010217 | H10: 0.024821 | P10: =IF(SUM(D10:O10)=0,"0",AVERAGEIF(D10:O10,"<>0",D10:O10))
A11: 10 | B11: 代理工商业购电价格 | C11: 冀北 | D11: =D12+D13 | E11: =E12+E13 | F11: =F12+F13 | G11: =G12+G13 | H11: =H12+H13 | I11: =I12+I13 | J11: =J12+J13 | K11: =K12+K13 | ... O11: =O12+O13 | P11: =IF(SUM(D11:O11)=0,"0",AVERAGEIF(D11:O11,"<>0",D11:O11))
A12: 11 | B12: （1）当月平均购电价格 | C12: 冀北 | D12: 0.394392 | E12: 0.393721 | F12: 0.394591 | G12: 0.39631 | H12: 0.396508 | P12: =IF(SUM(D12:O12)=0,"0",AVERAGEIF(D12:O12,"<>0",D12:O12))
A13: 12 | B13: （2）历史偏差电费折价 | C13: 冀北 | D13: -0.016618 | E13: -0.00083 | F13: 0.014418 | G13: 0.020997 | H13: 0.027731 | P13: =IF(SUM(D13:O13)=0,"0",AVERAGEIF(D13:O13,"<>0",D13:O13))
A14: 13 | B14: 代理工商业购电价格 | C14: 山东 | D14: =D15+D16+D17 | E14: =E15+E16+E17 | F14: =F15+F16+F17 | G14: =G15+G16+G17 | H14: =H15+H16+H17 | I14: =I15+I16+I17 | J14: =J15+J16+J17 | K14: =K15+K16+K17 | ... O14: =O15+O16+O17 | P14: =IF(SUM(D14:O14)=0,"0",AVERAGEIF(D14:O14,"<>0",D14:O14))
A15: 14 | B15: （1）当月平均购电价格 | C15: 山东 | D15: 0.3767 | E15: 0.3431 | F15: 0.3004 | G15: 0.2862 | H15: 0.2993 | P15: =IF(SUM(D15:O15)=0,"0",AVERAGEIF(D15:O15,"<>0",D15:O15))
A16: 15 | B16: （2）容量补偿电价 | C16: 山东 | D16: =0.0705 | E16: 0.0705 | F16: 0.0705 | G16: 0.0705 | H16: 0.0705 | P16: =IF(SUM(D16:O16)=0,"0",AVERAGEIF(D16:O16,"<>0",D16:O16))
A17: 16 | B17: （3）历史偏差电费折价 | C17: 山东 | D17: -0.0112 | E17: -0.0247 | F17: -0.0334 | G17: -0.0452 | H17: -0.016 | P17: =IF(SUM(D17:O17)=0,"0",AVERAGEIF(D17:O17,"<>0",D17:O17))
A18: 17 | B18: 代理工商业购电价格 | C18: 山西 | D18: =D19+D20 | E18: =E19+E20 | F18: =F19+F20 | G18: =G19+G20 | H18: =H19+H20 | I18: =I19+I20 | J18: =J19+J20 | K18: =K19+K20 | ... O18: =O19+O20 | P18: =IF(SUM(D18:O18)=0,"0",AVERAGEIF(D18:O18,"<>0",D18:O18))
A19: 18 | B19: （1）当月平均购电价格 | C19: 山西 | D19: 0.3041 | E19: 0.29125 | F19: 0.283758 | G19: 0.291545 | H19: 0.279485 | P19: =IF(SUM(D19:O19)=0,"0",AVERAGEIF(D19:O19,"<>0",D19:O19))
A20: 19 | B20: （2）历史偏差电费折价 | C20: 山西 | D20: -0.008232 | E20: 0.014146 | F20: 0.005836 | G20: 0.031408 | H20: -0.006153 | P20: =IF(SUM(D20:O20)=0,"0",AVERAGEIF(D20:O20,"<>0",D20:O20))
A21: 20 | B21: 代理工商业购电价格 | C21: 蒙西 | D21: =D22+D23 | E21: =E22+E23 | F21: =F22+F23 | G21: =G22+G23 | H21: =H22+H23 | I21: =I22+I23 | J21: =J22+J23 | K21: =K22+K23 | ... O21: =O22+O23 | P21: =IF(SUM(D21:O21)=0,"0",AVERAGEIF(D21:O21,"<>0",D21:O21))
A22: 21 | B22: （1）当月平均购电价格 | C22: 蒙西 | D22: 0.2863 | E22: 0.2815 | F22: 0.2834 | G22: 0.2788 | H22: 0.2732 | P22: =IF(SUM(D22:O22)=0,"0",AVERAGEIF(D22:O22,"<>0",D22:O22))
A23: 22 | B23: （2）历史偏差电费折价 | C23: 蒙西 | D23: 0.0339 | E23: 0.0442 | F23: 0.0294 | G23: 0.0429 | H23: 0.0562 | P23: =IF(SUM(D23:O23)=0,"0",AVERAGEIF(D23:O23,"<>0",D23:O23))
A24: 23 | B24: 代理工商业购电价格 | C24: 上海 | D24: =D25+D26 | E24: =E25+E26 | F24: =F25+F26 | G24: =G25+G26 | H24: =H25+H26 | I24: =I25+I26 | J24: =J25+J26 | K24: =K25+K26 | ... O24: =O25+O26 | P24: =IF(SUM(D24:O24)=0,"0",AVERAGEIF(D24:O24,"<>0",D24:O24))
A25: 24 | B25: （1）当月平均购电价格 | C25: 上海 | D25: 0.4773 | E25: 0.475275 | F25: 0.453585 | G25: 0.447219 | H25: 0.459464 | P25: =IF(SUM(D25:O25)=0,"0",AVERAGEIF(D25:O25,"<>0",D25:O25))
A26: 25 | B26: （2）历史偏差电费折价 | C26: 上海 | D26: -0.0448 | E26: -0.045009 | F26: -0.014508 | G26: -0.038055 | H26: -0.033421 | P26: =IF(SUM(D26:O26)=0,"0",AVERAGEIF(D26:O26,"<>0",D26:O26))
A27: 26 | B27: 代理工商业购电价格 | C27: 江苏 | D27: =D28+D29 | E27: =E28+E29 | F27: =F28+F29 | G27: =G28+G29 | H27: =H28+H29 | I27: =I28+I29 | J27: =J28+J29 | K27: =K28+K29 | ... O27: =O28+O29 | P27: =IF(SUM(D27:O27)=0,"0",AVERAGEIF(D27:O27,"<>0",D27:O27))
A28: 27 | B28: （1）当月平均购电价格 | C28: 江苏 | D28: 0.3959 | E28: 0.3153 | F28: 0.3698 | G28: 0.3746 | H28: 0.366 | P28: =IF(SUM(D28:O28)=0,"0",AVERAGEIF(D28:O28,"<>0",D28:O28))
A29: 28 | B29: （2）历史偏差电费折价 | C29: 江苏 | D29: -0.0022 | E29: -0.0051 | F29: -0.024 | G29: -0.0031 | H29: -0.0131 | P29: =IF(SUM(D29:O29)=0,"0",AVERAGEIF(D29:O29,"<>0",D29:O29))
A30: 29 | B30: 代理工商业购电价格 | C30: 浙江 | D30: =D31+D32 | E30: =E31+E32 | F30: =F31+F32 | G30: =G31+G32 | H30: =H31+H32 | I30: =I31+I32 | J30: =J31+J32 | K30: =K31+K32 | ... O30: =O31+O32 | P30: =IF(SUM(D30:O30)=0,"0",AVERAGEIF(D30:O30,"<>0",D30:O30))
A31: 30 | B31: （1）当月平均购电价格 | C31: 浙江 | D31: 0.369526 | E31: 0.348541 | F31: 0.367624 | G31: 0.353313 | H31: 0.363202 | P31: =IF(SUM(D31:O31)=0,"0",AVERAGEIF(D31:O31,"<>0",D31:O31))
A32: 31 | B32: （2）历史偏差电费折价 | C32: 浙江 | D32: 0.03906 | E32: 0.038114 | F32: 0.00433 | G32: -0.000655 | H32: 0.008665 | P32: =IF(SUM(D32:O32)=0,"0",AVERAGEIF(D32:O32,"<>0",D32:O32))
A33: 32 | B33: 代理工商业购电价格 | C33: 安徽 | D33: =D34+D35 | E33: =E34+E35 | F33: =F34+F35 | G33: =G34+G35 | H33: =H34+H35 | I33: =I34+I35 | J33: =J34+J35 | K33: =K34+K35 | ... O33: =O34+O35 | P33: =IF(SUM(D33:O33)=0,"0",AVERAGEIF(D33:O33,"<>0",D33:O33))
A34: 33 | B34: （1）当月平均购电价格 | C34: 安徽 | D34: 0.35766 | E34: 0.34625 | F34: 0.34747 | G34: 0.35533 | H34: 0.36176 | P34: =IF(SUM(D34:O34)=0,"0",AVERAGEIF(D34:O34,"<>0",D34:O34))
A35: 34 | B35: （2）历史偏差电费折价 | C35: 安徽 | D35: -0.0098 | E35: 0.0132 | F35: -0.0105 | G35: -0.0108 | H35: -0.0163 | P35: =IF(SUM(D35:O35)=0,"0",AVERAGEIF(D35:O35,"<>0",D35:O35))
A36: 35 | B36: 代理工商业购电价格 | C36: 福建 | D36: =D37+D38 | E36: =E37+E38 | F36: =F37+F38 | G36: =G37+G38 | H36: =H37+H38 | I36: =I37+I38 | J36: =J37+J38 | K36: =K37+K38 | ... O36: =O37+O38 | P36: =IF(SUM(D36:O36)=0,"0",AVERAGEIF(D36:O36,"<>0",D36:O36))
A37: 36 | B37: （1）当月平均购电价格 | C37: 福建 | D37: 0.369438 | E37: 0.368022 | F37: 0.366422 | G37: 0.370391 | H37: 0.371386 | P37: =IF(SUM(D37:O37)=0,"0",AVERAGEIF(D37:O37,"<>0",D37:O37))
A38: 37 | B38: （2）历史偏差电费折价 | C38: 福建 | D38: 0.017317 | E38: 0.011468 | F38: 0.00041 | G38: -0.004775 | H38: -0.000847 | P38: =IF(SUM(D38:O38)=0,"0",AVERAGEIF(D38:O38,"<>0",D38:O38))
A39: 38 | B39: 代理工商业购电价格 | C39: 湖北 | D39: =D40+D41 | E39: =E40+E41 | F39: =F40+F41 | G39: =G40+G41 | H39: =H40+H41 | I39: =I40+I41 | J39: =J40+J41 | K39: =K40+K41 | ... O39: =O40+O41 | P39: =IF(SUM(D39:O39)=0,"0",AVERAGEIF(D39:O39,"<>0",D39:O39))
A40: 39 | B40: （1）当月平均购电价格 | C40: 湖北 | D40: 0.38809 | E40: 0.39113 | F40: 0.39006 | G40: 0.40092 | H40: 0.39838 | P40: =IF(SUM(D40:O40)=0,"0",AVERAGEIF(D40:O40,"<>0",D40:O40))
...

Sheet 分表2-2026上网环节线损
A1: 序号 | B1: 2026年上网环节线损费用折价 | C1: 1月 | D1: 2月 | E1: 3月 | F1: 4月 | G1: 5月 | H1: 6月 | I1: 7月 | J1: 8月 | K1: 9月 | L1: 10月 | M1: 11月 | N1: 12月 | O1: 年均 | P1: 趋势图
A2: 1 | B2: 北京 | C2: 0.011414 | D2: 0.011381 | E2: 0.011381 | F2: 0.011381 | G2: 0.011381 | O2: =IF(SUM(C2:N2)=0,"0",AVERAGEIF(C2:N2,"<>0",C2:N2))
A3: 2 | B3: 天津 | C3: 0.016229 | D3: 0.016119 | E3: 0.016134 | F3: 0.016178 | G3: 0.016133 | O3: =IF(SUM(C3:N3)=0,"0",AVERAGEIF(C3:N3,"<>0",C3:N3))
A4: 3 | B4: 河北南网 | C4: 0.022091 | D4: 0.021364 | E4: 0.021081 | F4: 0.024398 | G4: 0.023756 | O4: =IF(SUM(C4:N4)=0,"0",AVERAGEIF(C4:N4,"<>0",C4:N4))
A5: 4 | B5: 冀北 | C5: 0.016433 | D5: 0.016405 | E5: 0.016441 | F5: 0.016513 | G5: 0.016521 | O5: =IF(SUM(C5:N5)=0,"0",AVERAGEIF(C5:N5,"<>0",C5:N5))
A6: 5 | B6: 山东 | C6: 0.0119 | D6: 0.0115 | E6: 0.0116 | F6: 0.0115 | G6: 0.0118 | O6: =IF(SUM(C6:N6)=0,"0",AVERAGEIF(C6:N6,"<>0",C6:N6))
A7: 6 | B7: 山西 | C7: 0.014417 | D7: 0.014205 | E7: 0.014018 | F7: 0.011532 | G7: 0.011205 | O7: =IF(SUM(C7:N7)=0,"0",AVERAGEIF(C7:N7,"<>0",C7:N7))
A8: 7 | B8: 蒙西 | C8: 0.0091 | D8: 0.0089 | E8: 0.009 | F8: 0.0088 | G8: 0.0087 | O8: =IF(SUM(C8:N8)=0,"0",AVERAGEIF(C8:N8,"<>0",C8:N8))
A9: 8 | B9: 上海 | C9: 0.0125 | D9: 0.012437 | E9: 0.011869 | F9: 0.011702 | G9: 0.012023 | O9: =IF(SUM(C9:N9)=0,"0",AVERAGEIF(C9:N9,"<>0",C9:N9))
A10: 9 | B10: 江苏 | C10: 0.013 | D10: 0.0104 | E10: 0.0121 | F10: 0.0123 | G10: 0.012 | O10: =IF(SUM(C10:N10)=0,"0",AVERAGEIF(C10:N10,"<>0",C10:N10))
A11: 10 | B11: 浙江 | C11: 0.013871 | D11: 0.007591 | E11: 0.011512 | F11: 0.014048 | G11: 0.011174 | O11: =IF(SUM(C11:N11)=0,"0",AVERAGEIF(C11:N11,"<>0",C11:N11))
A12: 11 | B12: 安徽 | C12: 0.0145 | D12: 0.0149 | E12: 0.014 | F12: 0.0143 | G12: 0.0144 | O12: =IF(SUM(C12:N12)=0,"0",AVERAGEIF(C12:N12,"<>0",C12:N12))
A13: 12 | B13: 福建 | C13: 0.013796 | D13: 0.013744 | E13: 0.013684 | F13: 0.013832 | G13: 0.013869 | O13: =IF(SUM(C13:N13)=0,"0",AVERAGEIF(C13:N13,"<>0",C13:N13))
... A33: 32 | B33: 海南 | C33: 0.02487 | D33: 0.021986 | E33: 0.02043 | F33: 0.021519 | G33: 0.024158 | O33: =IF(SUM(C33:N33)=0,"0",AVERAGEIF(C33:N33,"<>0",C33:N33))

Sheet 分表3-2026系统运行费
A1: 序号 | B1: 2026年代理购电价格 | C1: 省份 | D1: 1月 | E1: 2月 | F1: 3月 | G1: 4月 | H1: 5月 | I1: 6月 | J1: 7月 | K1: 8月 | L1: 9月 | M1: 10月 | N1: 11月 | O1: 12月 | P1: 省份 | Q1: 1月 | R1: 2月 | S1: 3月 | T1: 4月 | U1: 5月 | V1: 6月 | W1: 7月 | X1: 8月 | Y1: 9月 | Z1: 10月 | AA1: 11月 | AB1: 12月 | AC1: 省份 | AD1: 1月 | AE1: 2月 | AF1: 3月 | AG1: 4月 | AH1: 5月 | AI1: 6月 | AJ1: 7月 | AK1: 8月 | AL1: 9月 | AM1: 10月 | AN1: 11月 | AO1: 12月 | AP1: 省份 | AQ1: 1月 | AR1: 2月 | AS1: 3月 | AT1: 4月 | AU1: 5月 | AV1: 6月 | AW1: 7月 | AX1: 8月 | AY1: 9月 | AZ1: 10月 | BA1: 11月 | BB1: 12月 | BC1: 省份 | BD1: 1月 | BE1: 2月 | BF1: 3月 | BG1: 4月 | BH1: 5月 | BI1: 6月 | BJ1: 7月 | BK1: 8月 | BL1: 9月 | BM1: 10月 | BN1: 11月 | BO1: 12月 | BP1: 省份 | BQ1: 1月 | BR1: 2月 | BS1: 3月 | BT1: 4月 | BU1: 5月 | BV1: 6月 | BW1: 7月 | BX1: 8月 | BY1: 9月 | BZ1: 10月 | CA1: 11月 | CB1: 12月 | CC1: 省份 | CD1: 1月 | CE1: 2月 | CF1: 3月 | CG1: 4月 | CH1: 5月 | CI1: 6月 | CJ1: 7月 | CK1: 8月 | CL1: 9月 | CM1: 10月 | CN1: 11月 | CO1: 12月 | CP1: 省份 | CQ1: 1月 | CR1: 2月 | CS1: 3月 | CT1: 4月 | CU1: 5月 | CV1: 6月 | CW1: 7月 | CX1: 8月 | CY1: 9月 | CZ1: 10月 | DA1: 11月 | DB1: 12月 | DC1: 省份 | DD1: 1月 | DE1: 2月 | DF1: 3月 | DG1: 4月 | DH1: 5月 | DI1: 6月 | DJ1: 7月 | DK1: 8月 | DL1: 9月 | DM1: 10月 | DN1: 11月 | DO1: 12月 | DP1: 省份 | DQ1: 1月 | DR1: 2月 | DS1: 3月 | DT1: 4月 | DU1: 5月 | DV1: 6月 | DW1: 7月 | DX1: 8月 | DY1: 9月 | DZ1: 10月 | EA1: 11月 | EB1: 12月 | EC1: 省份 | ED1: 1月 | EE1: 2月 | EF1: 3月 | EG1: 4月 | EH1: 5月 | EI1: 6月 | EJ1: 7月 | EK1: 8月 | EL1: 9月 | EM1: 10月 | EN1: 11月 | EO1: 12月 | EP1: 省份 | EQ1: 1月 | ER1: 2月 | ES1: 3月 | ET1: 4月 | EU1: 5月 | EV1: 6月 | EW1: 7月 | EX1: 8月 | EY1: 9月 | EZ1: 10月 | FA1: 11月 | FB1: 12月 | FC1: 省份 | FD1: 1月 | FE1: 2月 | FF1: 3月 | FG1: 4月 | FH1: 5月 | FI1: 6月 | FJ1: 7月 | FK1: 8月 | FL1: 9月 | FM1: 10月 | FN1: 11月 | FO1: 12月 | FP1: 省份 | FQ1: 1月 | FR1: 2月 | FS1: 3月 | FT1: 4月 | FU1: 5月 | FV1: 6月 | FW1: 7月 | FX1: 8月 | FY1: 9月 | FZ1: 10月 | GA1: 11月 | GB1: 12月 | GC1: 省份 | GD1: 1月 | GE1: 2月 | GF1: 3月 | GG1: 4月 | GH1: 5月 | GI1: 6月 | GJ1: 7月 | GK1: 8月 | GL1: 9月 | GM1: 10月 | GN1: 11月 | GO1: 12月 | GP1: 省份 | GQ1: 1月 | GR1: 2月 | GS1: 3月 | GT1: 4月 | GU1: 5月 | GV1: 6月 | GW1: 7月 | GX1: 8月 | GY1: 9月 | GZ1: 10月 | HA1: 11月 | HB1: 12月 | HC1: 省份 | HD1: 1月 | HE1: 2月 | HF1: 3月 | HG1: 4月 | HH1: 5月 | HI1: 6月 | HJ1: 7月 | HK1: 8月 | HL1: 9月 | HM1: 10月 | HN1: 11月 | HO1: 12月 | HP1: 省份 | HQ1: 1月 | HR1: 2月 | HS1: 3月 | HT1: 4月 | HU1: 5月 | HV1: 6月 | HW1: 7月 | HX1: 8月 | HY1: 9月 | HZ1: 10月 | IA1: 11月 | IB1: 12月 | IC1: 省份 | ID1: 1月 | IE1: 2月 | IF1: 3月 | IG1: 4月 | IH1: 5月 | II1: 6月 | IJ1: 7月 | IK1: 8月 | IL1: 9月 | IM1: 10月 | IN1: 11月 | IO1: 12月 | IP1: 省份 | IQ1: 1月 | IR1: 2月 | IS1: 3月 | IT1: 4月 | IU1: 5月 | IV1: 6月 | IW1: 7月 | IX1: 8月 | IY1: 9月 | IZ1: 10月 | JA1: 11月 | JB1: 12月 | JC1: 省份 | JD1: 1月 | JE1: 2月 | JF1: 3月 | JG1: 4月 | JH1: 5月 | JI1: 6月 | JJ1: 7月 | JK1: 8月 | JL1: 9月 | JM1: 10月 | JN1: 11月 | JO1: 12月 | JP1: 省份 | JQ1: 1月 | JR1: 2月 | JS1: 3月 | JT1: 4月 | JU1: 5月 | JV1: 6月 | JW1: 7月 | JX1: 8月 | JY1: 9月 | JZ1: 10月 | KA1: 11月 | KB1: 12月 | KC1: 省份 | KD1: 1月 | KE1: 2月 | KF1: 3月 | KG1: 4月 | KH1: 5月 | KI1: 6月 | KJ1: 7月 | KK1: 8月 | KL1: 9月 | KM1: 10月 | KN1: 11月 | KO1: 12月 | KP1: 省份 | KQ1: 1月 | KR1: 2月 | KS1: 3月 | KT1: 4月 | KU1: 5月 | KV1: 6月 | KW1: 7月 | KX1: 8月 | KY1: 9月 | KZ1: 10月 | LA1: 11月 | LB1: 12月 | LC1: 省份 | LD1: 1月 | LE1: 2月 | LF1: 3月 | LG1: 4月 | LH1: 5月 | LI1: 6月 | LJ1: 7月 | LK1: 8月 | LL1: 9月 | LM1: 10月 | LN1: 11月 | LO1: 12月 | LP1: 省份 | LQ1: 1月 | LR1: 2月 | LS1: 3月 | LT1: 4月 | LU1: 5月 | LV1: 6月 | LW1: 7月 | LX1: 8月 | LY1: 9月 | LZ1: 10月 | MA1: 11月 | MB1: 12月 | MC1: 省份 | MD1: 1月 | ME1: 2月 | MF1: 3月 | MG1: 4月 | MH1: 5月 | MI1: 6月 | MJ1: 7月 | MK1: 8月 | ML1: 9月 | MM1: 10月 | MN1: 11月 | MO1: 12月 | MP1: 省份 | MQ1: 1月 | MR1: 2月 | MS1: 3月 | MT1: 4月 | MU1: 5月 | MV1: 6月 | MW1: 7月 | MX1: 8月 | MY1: 9月 | MZ1: 10月 | NA1: 11月 | NB1: 12月 | NC1: 省份 | ND1: 1月 | NE1: 2月 | NF1: 3月 | NG1: 4月 | NH1: 5月 | NI1: 6月 | NJ1: 7月 | NK1: 8月 | NL1: 9月 | NM1: 10月 | NN1: 11月 | NO1: 12月 | NP1: 省份 | NQ1: 1月 | NR1: 2月 | NS1: 3月 | NT1: 4月 | NU1: 5月 | NV1: 6月 | NW1: 7月 | NX1: 8月 | NY1: 9月 | NZ1: 10月 | OA1: 11月 | OB1: 12月 | OC1: 省份 | OD1: 1月 | OE1: 2月 | OF1: 3月 | OG1: 4月 | OH1: 5月 | OI1: 6月 | OJ1: 7月 | OK1: 8月 | OL1: 9月 | OM1: 10月 | ON1: 11月 | OO1: 12月 | OP1: 省份 | OQ1: 1月 | OR1: 2月 | OS1: 3月 | OT1: 4月 | OU1: 5月 | OV1: 6月 | OW1: 7月 | OX1: 8月 | OY1: 9月 | OZ1: 10月 | PA1: 11月 | PB1: 12月
A2: 1 | B2: 系统运行费用折合度电水平 | C2: 北京 | D2: =SUM(D3:D24) | E2: =SUM(E3:E24) | F2: =SUM(F3:F24) | G2: =SUM(G3:G24) | H2: =SUM(H3:H24) | I2: =SUM(I3:I24) | J2: =SUM(J3:J24) | K2: =SUM(K3:K24) | ... O2: =SUM(O3:O24) | P2: 天津 | Q2: =SUM(Q3:Q24) | R2: =SUM(R3:R24) | S2: =SUM(S3:S24) | T2: =SUM(T3:T24) | U2: =SUM(U3:U24) | V2: =SUM(V3:V24) | W2: =SUM(W3:W24) | X2: =SUM(X3:X24) | ... AB2: =SUM(AB3:AB24) | AC2: 河北南网 | AD2: =SUM(AD3:AD24) | AE2: =SUM(AE3:AE24) | AF2: =SUM(AF3:AF24) | AG2: =SUM(AG3:AG24) | AH2: =SUM(AH3:AH24) | AI2: =SUM(AI3:AI24) | AJ2: =SUM(AJ3:AJ24) | AK2: =SUM(AK3:AK24) | ... AO2: =SUM(AO3:AO24) | AP2: 冀北 | AQ2: =SUM(AQ3:AQ24) | AR2: =SUM(AR3:AR24) | AS2: =SUM(AS3:AS24) | AT2: =SUM(AT3:AT24) | AU2: =SUM(AU3:AU24) | AV2: =SUM(AV3:AV24) | AW2: =SUM(AW3:AW24) | AX2: =SUM(AX3:AX24) | ... BB2: =SUM(BB3:BB24) | BC2: 山东 | BD2: =SUM(BD3:BD24) | BE2: =SUM(BE3:BE24) | BF2: =SUM(BF3:BF24) | BG2: =SUM(BG3:BG24) | BH2: =SUM(BH3:BH24) | BI2: =SUM(BI3:BI24) | BJ2: =SUM(BJ3:BJ24) | BK2: =SUM(BK3:BK24) | ... BO2: =SUM(BO3:BO24) | BP2: 山西 | BQ2: =SUM(BQ3:BQ24) | BR2: =SUM(BR3:BR24) | BS2: =SUM(BS3:BS24) | BT2: =SUM(BT3:BT24) | BU2: =SUM(BU3:BU24) | BV2: =SUM(BV3:BV24) | BW2: =SUM(BW3:BW24) | BX2: =SUM(BX3:BX24) | ... CB2: =SUM(CB3:CB24) | CC2: 蒙西 | CD2: =SUM(CD3:CD24) | CE2: =SUM(CE3:CE24) | CF2: =SUM(CF3:CF24) | CG2: =SUM(CG3:CG24) | CH2: =SUM(CH3:CH24) | CI2: =SUM(CI3:CI24) | CJ2: =SUM(CJ3:CJ24) | CK2: =SUM(CK3:CK24) | ... CO2: =SUM(CO3:CO24) | CP2: 上海 | CQ2: =SUM(CQ3:CQ24) | CR2: =SUM(CR3:CR24) | CS2: =SUM(CS3:CS24) | CT2: =SUM(CT3:CT24) | CU2: =SUM(CU3:CU24) | CV2: =SUM(CV3:CV24) | CW2: =SUM(CW3:CW24) | CX2: =SUM(CX3:CX24) | ... DB2: =SUM(DB3:DB24) | DC2: 江苏 | DD2: =SUM(DD3:DD24) | DE2: =SUM(DE3:DE24) | DF2: =SUM(DF3:DF24) | DG2: =SUM(DG3:DG24) | DH2: =SUM(DH3:DH24) | DI2: =SUM(DI3:DI24) | DJ2: =SUM(DJ3:DJ24) | DK2: =SUM(DK3:DK24) | ... DO2: =SUM(DO3:DO24) | DP2: 浙江 | DQ2: =SUM(DQ3:DQ24) | DR2: =SUM(DR3:DR24) | DS2: =SUM(DS3:DS24) | DT2: =SUM(DT3:DT24) | DU2: =SUM(DU3:DU24) | DV2: =SUM(DV3:DV24) | DW2: =SUM(DW3:DW24) | DX2: =SUM(DX3:DX24) | ... EB2: =SUM(EB3:EB24) | EC2: 安徽 | ED2: =SUM(ED3:ED24) | EE2: =SUM(EE3:EE24) | EF2: =SUM(EF3:EF24) | EG2: =SUM(EG3:EG24) | EH2: =SUM(EH3:EH24) | EI2: =SUM(EI3:EI24) | EJ2: =SUM(EJ3:EJ24) | EK2: =SUM(EK3:EK24) | ... EO2: =SUM(EO3:EO24) | EP2: 福建 | EQ2: =SUM(EQ3:EQ24) | ER2: =SUM(ER3:ER24) | ES2: =SUM(ES3:ES24) | ET2: =SUM(ET3:ET24) | EU2: =SUM(EU3:EU24) | EV2: =SUM(EV3:EV24) | EW2: =SUM(EW3:EW24) | EX2: =SUM(EX3:EX24) | ... FB2: =SUM(FB3:FB24) | FC2: 湖北 | FD2: =SUM(FD3:FD24) | FE2: =SUM(FE3:FE24) | FF2: =SUM(FF3:FF24) | FG2: =SUM(FG3:FG24) | FH2: =SUM(FH3:FH24) | FI2: =SUM(FI3:FI24) | FJ2: =SUM(FJ3:FJ24) | FK2: =SUM(FK3:FK24) | ... FO2: =SUM(FO3:FO24) | FP2: 河南 | FQ2: =SUM(FQ3:FQ24) | FR2: =SUM(FR3:FR24) | FS2: =SUM(FS3:FS24) | FT2: =SUM(FT3:FT24) | FU2: =SUM(FU3:FU24) | FV2: =SUM(FV3:FV24) | FW2: =SUM(FW3:FW24) | FX2: =SUM(FX3:FX24) | ... GB2: =SUM(GB3:GB24) | GC2: 湖南 | GD2: =SUM(GD3:GD24) | GE2: =SUM(GE3:GE24) | GF2: =SUM(GF3:GF24) | GG2: =SUM(GG3:GG24) | GH2: =SUM(GH3:GH24) | GI2: =SUM(GI3:GI24) | GJ2: =SUM(GJ3:GJ24) | GK2: =SUM(GK3:GK24) | ... GO2: =SUM(GO3:GO24) | GP2: 江西 | GQ2: =SUM(GQ3:GQ24) | GR2: =SUM(GR3:GR24) | GS2: =SUM(GS3:GS24) | GT2: =SUM(GT3:GT24) | GU2: =SUM(GU3:GU24) | GV2: =SUM(GV3:GV24) | GW2: =SUM(GW3:GW24) | GX2: =SUM(GX3:GX24) | ... HB2: =SUM(HB3:HB24) | HC2: 辽宁 | HD2: =SUM(HD3:HD24) | HE2: =SUM(HE3:HE24) | HF2: =SUM(HF3:HF24) | HG2: =SUM(HG3:HG24) | HH2: =SUM(HH3:HH24) | HI2: =SUM(HI3:HI24) | HJ2: =SUM(HJ3:HJ24) | HK2: =SUM(HK3:HK24) | ... HO2: =SUM(HO3:HO24) | HP2: 吉林 | HQ2: =SUM(HQ3:HQ24) | HR2: =SUM(HR3:HR24) | HS2: =SUM(HS3:HS24) | HT2: =SUM(HT3:HT24) | HU2: =SUM(HU3:HU24) | HV2: =SUM(HV3:HV24) | HW2: =SUM(HW3:HW24) | HX2: =SUM(HX3:HX24) | ... IB2: =SUM(IB3:IB24) | IC2: 黑龙江 | ID2: =SUM(ID3:ID24) | IE2: =SUM(IE3:IE24) | IF2: =SUM(IF3:IF24) | IG2: =SUM(IG3:IG24) | IH2: =SUM(IH3:IH24) | II2: =SUM(II3:II24) | IJ2: =SUM(IJ3:IJ24) | IK2: =SUM(IK3:IK24) | ... IO2: =SUM(IO3:IO24) | IP2: 蒙东 | IQ2: =SUM(IQ3:IQ24) | IR2: =SUM(IR3:IR24) | IS2: =SUM(IS3:IS24) | IT2: =SUM(IT3:IT24) | IU2: =SUM(IU3:IU24) | IV2: =SUM(IV3:IV24) | IW2: =SUM(IW3:IW24) | IX2: =SUM(IX3:IX24) | ... JB2: =SUM(JB3:JB24) | JC2: 陕西 | JD2: =SUM(JD3:JD24) | JE2: =SUM(JE3:JE24) | JF2: =SUM(JF3:JF24) | JG2: =SUM(JG3:JG24) | JH2: =SUM(JH3:JH24) | JI2: =SUM(JI3:JI24) | JJ2: =SUM(JJ3:JJ24) | JK2: =SUM(JK3:JK24) | ... JO2: =SUM(JO3:JO24) | JP2: 甘肃 | JQ2: =SUM(JQ3:JQ24) | JR2: =SUM(JR3:JR24) | JS2: =SUM(JS3:JS24) | JT2: =SUM(JT3:JT24) | JU2: =SUM(JU3:JU24) | JV2: =SUM(JV3:JV24) | JW2: =SUM(JW3:JW24) | JX2: =SUM(JX3:JX24) | ... KB2: =SUM(KB3:KB24) | KC2: 青海 | KD2: =SUM(KD3:KD24) | KE2: =SUM(KE3:KE24) | KF2: =SUM(KF3:KF24) | KG2: =SUM(KG3:KG24) | KH2: =SUM(KH3:KH24) | KI2: =SUM(KI3:KI24) | KJ2: =SUM(KJ3:KJ24) | KK2: =SUM(KK3:KK24) | ... KO2: =SUM(KO3:KO24) | KP2: 宁夏 | KQ2: =SUM(KQ3:KQ24) | KR2: =SUM(KR3:KR24) | KS2: =SUM(KS3:KS24) | KT2: =SUM(KT3:KT24) | KU2: =SUM(KU3:KU24) | KV2: =SUM(KV3:KV24) | KW2: =SUM(KW3:KW24) | KX2: =SUM(KX3:KX24) | ... LB2: =SUM(LB3:LB24) | LC2: 新疆 | LD2: =SUM(LD3:LD24) | LE2: =SUM(LE3:LE24) | LF2: =SUM(LF3:LF24) | LG2: =SUM(LG3:LG24) | LH2: =SUM(LH3:LH24) | LI2: =SUM(LI3:LI24) | LJ2: =SUM(LJ3:LJ24) | LK2: =SUM(LK3:LK24) | ... LO2: =SUM(LO3:LO24) | LP2: 重庆 | LQ2: =SUM(LQ3:LQ24) | LR2: =SUM(LR3:LR24) | LS2: =SUM(LS3:LS24) | LT2: =SUM(LT3:LT24) | LU2: =SUM(LU3:LU24) | LV2: =SUM(LV3:LV24) | LW2: =SUM(LW3:LW24) | LX2: =SUM(LX3:LX24) | ... MB2: =SUM(MB3:MB24) | MC2: 四川 | MD2: =SUM(MD3:MD24) | ME2: =SUM(ME3:ME24) | MF2: =SUM(MF3:MF24) | MG2: =SUM(MG3:MG24) | MH2: =SUM(MH3:MH24) | MI2: =SUM(MI3:MI24) | MJ2: =SUM(MJ3:MJ24) | MK2: =SUM(MK3:MK24) | ... MO2: =SUM(MO3:MO24) | MP2: 广东 | MQ2: =SUM(MQ3:MQ24) | MR2: =SUM(MR3:MR24) | MS2: =SUM(MS3:MS24) | MT2: =SUM(MT3:MT24) | MU2: =SUM(MU3:MU24) | MV2: =SUM(MV3:MV24) | MW2: =SUM(MW3:MW24) | MX2: =SUM(MX3:MX24) | ... NB2: =SUM(NB3:NB24) | NC2: 广西 | ND2: =SUM(ND3:ND24) | NE2: =SUM(NE3:NE24) | NF2: =SUM(NF3:NF24) | NG2: =SUM(NG3:NG24) | NH2: =SUM(NH3:NH24) | NI2: =SUM(NI3:NI24) | NJ2: =SUM(NJ3:NJ24) | NK2: =SUM(NK3:NK24) | ... NO2: =SUM(NO3:NO24) | NP2: 云南 | NQ2: =SUM(NQ3:NQ24) | NR2: =SUM(NR3:NR24) | NS2: =SUM(NS3:NS24) | NT2: =SUM(NT3:NT24) | NU2: =SUM(NU3:NU24) | NV2: =SUM(NV3:NV24) | NW2: =SUM(NW3:NW24) | NX2: =SUM(NX3:NX24) | ... OB2: =SUM(OB3:OB24) | OC2: 贵州 | OD2: =SUM(OD3:OD24) | OE2: =SUM(OE3:OE24) | OF2: =SUM(OF3:OF24) | OG2: =SUM(OG3:OG24) | OH2: =SUM(OH3:OH24) | OI2: =SUM(OI3:OI24) | OJ2: =SUM(OJ3:OJ24) | OK2: =SUM(OK3:OK24) | ... OO2: =SUM(OO3:OO24) | OP2: 海南 | OQ2: -0.004545 | OR2: 0.137592 | OS2: 0.158319 | OT2: =SUM(OT3:OT24) | OU2: =SUM(OU3:OU24) | OV2: =SUM(OV3:OV24) | OW2: =SUM(OW3:OW24) | OX2: =SUM(OX3:OX24) | OY2: =SUM(OY3:OY24) | OZ2: =SUM(OZ3:OZ24) | PA2: =SUM(PA3:PA24) | PB2: =SUM(PB3:PB24)
A3: 2 | B3: （1）辅助服务费用折合度电水平 | C3: 北京 | D3: 0 | E3: 0 | F3: 0 | G3: 0 | H3: 0 | P3: 天津 | Q3: 0 | R3: 0 | S3: 0 | T3: 0 | U3: 0 | AC3: 河北南网 | AD3: 0 | AE3: 0 | AF3: 0.000268 | AG3: 0.000234 | AH3: 0.000129 | AP3: 冀北 | AQ3: 0 | AR3: 0 | AS3: 0 | AT3: 0 | AU3: 0 | BC3: 山东 | BD3: 0 | BE3: 0 | BF3: 0 | BG3: 0 | BH3: 0 | BP3: 山西 | BQ3: 0.003301 | BR3: 0.003978 | BS3: 0.003473 | BT3: 0.003409 | BU3: 0.003521 | CC3: 蒙西 | CD3: 0.0008 | CE3: 0.0008 | CF3: 0.0004 | CG3: 0.0002 | CH3: 0.0017 | CP3: 上海 | CQ3: 0 | CR3: 0 | CS3: 0 | CT3: 0 | CU3: 0 | DC3: 江苏 | DD3: 0 | DE3: 0 | DF3: 0 | DG3: 0 | DH3: 0 | DP3: 浙江 | DQ3: 0 | DR3: 0 | DS3: 0 | DT3: 0 | DU3: 0 | EC3: 安徽 | ED3: 0 | EE3: 0 | EF3: 0 | EG3: 0 | EH3: 0 | EP3: 福建 | EQ3: 0 | ER3: 0 | ES3: 0 | ET3: 0 | EU3: 0 | FC3: 湖北 | FD3: 0 | FE3: 0 | FF3: 0 | FG3: 0.001138 | FH3: 0.00216 | FP3: 河南 | FQ3: 0 | FR3: 0 | FS3: 0 | FT3: 0 | FU3: 0 | GC3: 湖南 | GD3: 0 | GE3: 0 | GF3: 0 | GG3: 0 | GH3: 0 | GP3: 江西 | GQ3: 0 | GR3: 0 | GS3: 0 | GT3: 0 | GU3: 0 | HC3: 辽宁 | HD3: 0 | HE3: 0 | HF3: 0.000837 | HG3: 0.000687 | HH3: 0.00085 | HP3: 吉林 | HQ3: 0.003522 | HR3: 0.002456 | HS3: 0.005913 | HT3: -0.001415 | HU3: -0.000551 | IC3: 黑龙江 | ID3: 0 | IE3: 0 | IF3: 0 | IG3: 0 | IH3: 0 | IP3: 蒙东 | IQ3: 0 | IR3: 0 | IS3: 0 | IT3: 0 | IU3: 0 | JC3: 陕西 | JD3: 0.0025 | JE3: 0.0039 | JF3: 0.004 | JG3: 0.0031 | JH3: 0.0036 | JP3: 甘肃 | JQ3: 0.014437 | JR3: 0.017761 | JS3: 0.005119 | JT3: 0.004951 | JU3: 0.007169 | KC3: 青海 | KP3: 宁夏 | KQ3: 0 | KR3: 0 | KS3: 0 | KT3: 0 | KU3: 0 | LC3: 新疆 | LD3: 0.005025 | LE3: 0.006606 | LF3: 0.005018 | LG3: 0.00554 | LH3: 0.005135 | LP3: 重庆 | LQ3: 0 | LR3: 0 | LS3: 0 | LT3: 0 | LU3: 0 | MC3: 四川 | MD3: 0.003082 | ME3: 0.003312 | MF3: 0.002128 | MG3: 0.001182 | MH3: 0.000698 | MP3: 广东 | MQ3: 0.0042 | MR3: 0.0034 | MS3: 0.0017 | MT3: 0.0033 | MU3: 0.0022 | NC3: 广西 | ND3: 0.003968 | NE3: 0.003964 | NF3: 0.003611 | NG3: 0.002955 | NH3: 0.003716 | NP3: 云南 | OC3: 贵州 | OD3: 0 | OE3: 0 | OF3: 0 | OG3: 0 | OH3: 0 | OP3: 海南 | OT3: 0.00216 | OU3: 0.001664
